Workbook

Sheet Inicio
B2: Simulacros de examen autocorregidos
B4: Dos exámenes de prueba de 5 preguntas (2 puntos cada una). Tiempo orientativo: 90 minutos cada uno.
B5: Haz cada simulacro de una sentada, con tus prácticas de clase y tu solucionario abiertos, como en el examen real.
B6: Escribe los resultados en las celdas amarillas: se corrigen solas. Haz los cálculos en la propia hoja.
B7: Las proporciones puedes darlas en decimal (0,25) o en porcentaje (25).
B9: Simulacro 1
B10: Pregunta | C10: Aciertos | D10: Puntos
B11: S1_P1 | C11: ='S1_P1'!$F$2&" de 12" | D11: =ROUND('S1_P1'!$F$2/12*2,2)
B12: S1_P2 | C12: ='S1_P2'!$F$2&" de 8" | D12: =ROUND('S1_P2'!$F$2/8*2,2)
B13: S1_P3 | C13: ='S1_P3'!$F$2&" de 7" | D13: =ROUND('S1_P3'!$F$2/7*2,2)
B14: S1_P4 | C14: ='S1_P4'!$F$2&" de 9" | D14: =ROUND('S1_P4'!$F$2/9*2,2)
B15: S1_P5 | C15: ='S1_P5'!$F$2&" de 6" | D15: =ROUND('S1_P5'!$F$2/6*2,2)
C16: Nota (sobre 10) | D16: =D11+D12+D13+D14+D15
B18: Simulacro 2
B19: Pregunta | C19: Aciertos | D19: Puntos
B20: S2_P1 | C20: ='S2_P1'!$F$2&" de 11" | D20: =ROUND('S2_P1'!$F$2/11*2,2)
B21: S2_P2 | C21: ='S2_P2'!$F$2&" de 8" | D21: =ROUND('S2_P2'!$F$2/8*2,2)
B22: S2_P3 | C22: ='S2_P3'!$F$2&" de 9" | D22: =ROUND('S2_P3'!$F$2/9*2,2)
B23: S2_P4 | C23: ='S2_P4'!$F$2&" de 9" | D23: =ROUND('S2_P4'!$F$2/9*2,2)
B24: S2_P5 | C24: ='S2_P5'!$F$2&" de 2" | D24: =ROUND('S2_P5'!$F$2/2*2,2)
C25: Nota (sobre 10) | D25: =D20+D21+D22+D23+D24

Sheet S1_P1
A1: Simulacro 1 · Pregunta 1 (2 puntos)
A2: Días de baja en el último año de 25 trabajadores | E2: Aciertos: | F2: =SUMPRODUCT(--(LEFT($C$1:$C$29,1)="✔")) | G2: de 12
A4: Celdas azules: datos. Celdas amarillas: tu respuesta (se ponen verdes si está bien y rojas si no).
A6: Días de baja en el último año de 25 trabajadores.
A7: Datos | B7: 0 | C7: 2 | D7: 1 | E7: 0 | F7: 3 | G7: 1 | H7: 0 | I7: 0 | J7: 2 | K7: 5
B8: 1 | C8: 0 | D8: 1 | E8: 2 | F8: 0 | G8: 9 | H8: 1 | I8: 0 | J8: 3 | K8: 1
B9: 2 | C9: 0 | D9: 1 | E9: 4 | F9: 0
A11: Preguntas
A12: Tamaño de la muestra (n) | C12: =IF(B12="","",IF(AND(ISNUMBER(B12),ABS(B12-Claves!$A$1)<=0.51),"✔ Bien",IF(NOT(ISNUMBER(B12)),"✘ Escribe solo el número (sin texto ni %).","✘ Revisa el cálculo.")))
A13: Media | C13: =IF(B13="","",IF(AND(ISNUMBER(B13),ABS(B13-Claves!$A$2)<=0.0051),"✔ Bien",IF(NOT(ISNUMBER(B13)),"✘ Escribe solo el número (sin texto ni %).",IF(ABS(B13-3.4285714285714284)<=0.0051,"✘ Has hecho la media de los valores distintos. Cada valor cuenta tantas veces como se repite.","✘ Revisa el cálculo."))))
A14: Mediana | C14: =IF(B14="","",IF(AND(ISNUMBER(B14),ABS(B14-Claves!$A$3)<=0.0051),"✔ Bien",IF(NOT(ISNUMBER(B14)),"✘ Escribe solo el número (sin texto ni %).","✘ Revisa el cálculo.")))
A15: Moda | C15: =IF(B15="","",IF(AND(ISNUMBER(B15),ABS(B15-Claves!$A$4)<=0.51),"✔ Bien",IF(NOT(ISNUMBER(B15)),"✘ Escribe solo el número (sin texto ni %).",IF(ABS(B15-9)<=0.51,"✘ Eso es la frecuencia más alta. La moda es el VALOR que tiene esa frecuencia.","✘ Revisa el cálculo."))))
A16: Primer cuartil (con CUARTIL.INC) | C16: =IF(B16="","",IF(AND(ISNUMBER(B16),ABS(B16-Claves!$A$5)<=0.0051),"✔ Bien",IF(NOT(ISNUMBER(B16)),"✘ Escribe solo el número (sin texto ni %).","✘ Revisa el cálculo.")))
A17: Tercer cuartil (con CUARTIL.INC) | C17: =IF(B17="","",IF(AND(ISNUMBER(B17),ABS(B17-Claves!$A$6)<=0.0051),"✔ Bien",IF(NOT(ISNUMBER(B17)),"✘ Escribe solo el número (sin texto ni %).","✘ Revisa el cálculo.")))
A18: Varianza S² (la de clase) | C18: =IF(B18="","",IF(AND(ISNUMBER(B18),ABS(B18-Claves!$A$7)<=0.0040864000000000004),"✔ Bien",IF(NOT(ISNUMBER(B18)),"✘ Escribe solo el número (sin texto ni %).",IF(ABS(B18-4.256666666666667)<=0.004256666666666667,"✘ Has calculado la cuasivarianza (VAR.S). Aquí se pide VAR.P.",IF(ABS(B18-6.52)<=0.00652,"✘ Te falta restar la media al cuadrado.","✘ Revisa el cálculo.")))))
A19: Cuasivarianza s² | C19: =IF(B19="","",IF(AND(ISNUMBER(B19),ABS(B19-Claves!$A$8)<=0.004256666666666667),"✔ Bien",IF(NOT(ISNUMBER(B19)),"✘ Escribe solo el número (sin texto ni %).",IF(ABS(B19-4.0864)<=0.0040864000000000004,"✘ Esa es la varianza (VAR.P). La cuasivarianza es VAR.S.","✘ Revisa el cálculo."))))
A20: Desviación típica S | C20: =IF(B20="","",IF(AND(ISNUMBER(B20),ABS(B20-Claves!$A$9)<=0.0020214846029589246),"✔ Bien",IF(NOT(ISNUMBER(B20)),"✘ Escribe solo el número (sin texto ni %).",IF(ABS(B20-2.0631690833925043)<=0.0020631690833925044,"✘ Has usado DESVEST.S. La desviación típica de clase es DESVEST.P.",IF(ABS(B20-4.0864)<=0.0040864000000000004,"✘ Eso es la varianza. La desviación típica es su raíz.","✘ Revisa el cálculo.")))))
A21: Coeficiente de variación (en decimal) | C21: =IF(B21="","",IF(AND(ISNUMBER(B21),OR(ABS(B21-Claves!$A$10)<=0.0012958234634352082,ABS(B21/100-Claves!$A$10)<=0.0012958234634352082)),"✔ Bien",IF(NOT(ISNUMBER(B21)),"✘ Escribe solo el número (sin texto ni %).",IF(OR(ABS(B21-1.3225442842259643)<=0.0013225442842259643,ABS(B21/100-1.3225442842259643)<=0.0013225442842259643),"✘ Usa DESVEST.P en el CV, no DESVEST.S.",IF(OR(ABS(B21-0.7717100579032697)<=0.0007717100579032697,ABS(B21/100-0.7717100579032697)<=0.0007717100579032697),"✘ Está al revés: CV = desviación típica ÷ media.","✘ Revisa el cálculo.")))))
A22: Proporción de empleados con más de 2 (en decimal o %) | C22: =IF(B22="","",IF(AND(ISNUMBER(B22),OR(ABS(B22-Claves!$A$11)<=0.00051,ABS(B22/100-Claves!$A$11)<=0.00051)),"✔ Bien",IF(NOT(ISNUMBER(B22)),"✘ Escribe solo el número (sin texto ni %).",IF(OR(ABS(B22-0.36)<=0.00051,ABS(B22/100-0.36)<=0.00051),"✘ ""Más de 2"" no incluye el 2.",IF(OR(ABS(B22-5)<=0.005,ABS(B22/100-5)<=0.005),"✘ Eso es cuántos son. Piden la proporción: divide entre n.","✘ Revisa el cálculo.")))))
A23: ¿Cuál es el único valor atípico? (límite superior C₃ + 1,5·IQR) | C23: =IF(B23="","",IF(AND(ISNUMBER(B23),ABS(B23-Claves!$A$12)<=0.51),"✔ Bien",IF(NOT(ISNUMBER(B23)),"✘ Escribe solo el número (sin texto ni %).",IF(ABS(B23-5)<=0.51,"✘ Para ser atípico tiene que ser MAYOR que el límite (2 + 1,5·2 = 5). El 5 no lo es.","✘ Revisa el cálculo."))))

Sheet S1_P2
A1: Simulacro 1 · Pregunta 2 (2 puntos)
A2: Salario mensual de 110 empleados | E2: Aciertos: | F2: =SUMPRODUCT(--(LEFT($C$1:$C$28,1)="✔")) | G2: de 8
A4: Celdas azules: datos. Celdas amarillas: tu respuesta (se ponen verdes si está bien y rojas si no).
A6: Salario mensual (€) de 110 empleados.
A7: Intervalo | B7: nᵢ
A8: [900, 1200] | B8: 12
A9: (1200, 1500] | B9: 30
A10: (1500, 1800] | B10: 38
A11: (1800, 2400] | B11: 24
A12: (2400, 3600] | B12: 6
A14: Preguntas
A15: n (total) | C15: =IF(B15="","",IF(AND(ISNUMBER(B15),ABS(B15-Claves!$A$13)<=0.51),"✔ Bien",IF(NOT(ISNUMBER(B15)),"✘ Escribe solo el número (sin texto ni %).","✘ Revisa el cálculo.")))
A16: Media | C16: =IF(B16="","",IF(AND(ISNUMBER(B16),ABS(B16-Claves!$A$14)<=1.6745454545454546),"✔ Bien",IF(NOT(ISNUMBER(B16)),"✘ Escribe solo el número (sin texto ni %).",IF(ABS(B16-1830)<=1.83,"✘ Has promediado las marcas sin multiplicar por las frecuencias.","✘ Revisa el cálculo."))))
A17: Varianza S² | C17: =IF(B17="","",IF(AND(ISNUMBER(B17),ABS(B17-Claves!$A$15)<=206.80661157024792),"✔ Bien",IF(NOT(ISNUMBER(B17)),"✘ Escribe solo el número (sin texto ni %).",IF(ABS(B17-3010909.090909091)<=3010.909090909091,"✘ Te falta restar la media al cuadrado.",IF(ABS(B17-208703.9199332777)<=208.70391993327772,"✘ Esa es la cuasivarianza (divide entre n−1). Aquí se pide la varianza.","✘ Revisa el cálculo.")))))
A18: Desviación típica S | C18: =IF(B18="","",IF(AND(ISNUMBER(B18),ABS(B18-Claves!$A$16)<=0.45475994939115727),"✔ Bien",IF(NOT(ISNUMBER(B18)),"✘ Escribe solo el número (sin texto ni %).","✘ Revisa el cálculo.")))
A19: Coeficiente de variación (decimal) | C19: =IF(B19="","",IF(AND(ISNUMBER(B19),OR(ABS(B19-Claves!$A$17)<=0.00051,ABS(B19/100-Claves!$A$17)<=0.00051)),"✔ Bien",IF(NOT(ISNUMBER(B19)),"✘ Escribe solo el número (sin texto ni %).","✘ Revisa el cálculo.")))
A20: Moda (fórmula de intervalos) | C20: =IF(B20="","",IF(AND(ISNUMBER(B20),ABS(B20-Claves!$A$18)<=1.5705882352941176),"✔ Bien",IF(NOT(ISNUMBER(B20)),"✘ Escribe solo el número (sin texto ni %).",IF(ABS(B20-1609.090909090909)<=1.6090909090909091,"✘ Has usado las frecuencias. Con amplitudes distintas, el intervalo modal se elige por la DENSIDAD.","✘ Revisa el cálculo."))))
A21: Mediana | C21: =IF(B21="","",IF(AND(ISNUMBER(B21),ABS(B21-Claves!$A$19)<=1.6026315789473684),"✔ Bien",IF(NOT(ISNUMBER(B21)),"✘ Escribe solo el número (sin texto ni %).",IF(ABS(B21-1650)<=1.6500000000000001,"✘ Eso es la marca del intervalo. Aplica la fórmula: Linf + (n/2 − Nᵢ₋₁)/nᵢ · aᵢ.","✘ Revisa el cálculo."))))
A22: ¿A partir de qué valor se está en el 10 % con valores más altos? | C22: =IF(B22="","",IF(AND(ISNUMBER(B22),ABS(B22-Claves!$A$20)<=2.275),"✔ Bien",IF(NOT(ISNUMBER(B22)),"✘ Escribe solo el número (sin texto ni %).",IF(ABS(B22-1175)<=1.175,"✘ Ese es el percentil 10. ""El 10 % de arriba"" empieza en el percentil 90.","✘ Revisa el cálculo."))))

Sheet S1_P3
A1: Simulacro 1 · Pregunta 3 (2 puntos)
A2: Turno y satisfacción | E2: Aciertos: | F2: =SUMPRODUCT(--(LEFT($C$1:$C$25,1)="✔")) | G2: de 7
A4: Celdas azules: datos. Celdas amarillas: tu respuesta (se ponen verdes si está bien y rojas si no).
A6: 140 trabajadores según turno (filas) y satisfacción (columnas).
A7: Turno \ Satisfacción | B7: Alta | C7: Media | D7: Baja
A8: Mañana | B8: 18 | C8: 22 | D8: 10
A9: Tarde | B9: 12 | C9: 20 | D9: 18
A10: Noche | B10: 6 | C10: 10 | D10: 24
A12: Preguntas
A13: n (total) | C13: =IF(B13="","",IF(AND(ISNUMBER(B13),ABS(B13-Claves!$A$21)<=0.51),"✔ Bien",IF(NOT(ISNUMBER(B13)),"✘ Escribe solo el número (sin texto ni %).","✘ Revisa el cálculo.")))
A14: Distribución marginal: total de "Media" | C14: =IF(B14="","",IF(AND(ISNUMBER(B14),ABS(B14-Claves!$A$22)<=0.51),"✔ Bien",IF(NOT(ISNUMBER(B14)),"✘ Escribe solo el número (sin texto ni %).","✘ Revisa el cálculo.")))
A15: f₁₁ (proporción de Mañana y Alta, en decimal) | C15: =IF(B15="","",IF(AND(ISNUMBER(B15),OR(ABS(B15-Claves!$A$23)<=0.00051,ABS(B15/100-Claves!$A$23)<=0.00051)),"✔ Bien",IF(NOT(ISNUMBER(B15)),"✘ Escribe solo el número (sin texto ni %).","✘ Revisa el cálculo.")))
A16: f₁. × f.₁ (lo que habría si fueran independientes) | C16: =IF(B16="","",IF(AND(ISNUMBER(B16),OR(ABS(B16-Claves!$A$24)<=0.00051,ABS(B16/100-Claves!$A$24)<=0.00051)),"✔ Bien",IF(NOT(ISNUMBER(B16)),"✘ Escribe solo el número (sin texto ni %).","✘ Revisa el cálculo.")))
A17: De los de Noche, ¿qué proporción es "Baja"? (Satisfacción | Turno = Noche) | C17: =IF(B17="","",IF(AND(ISNUMBER(B17),OR(ABS(B17-Claves!$A$25)<=0.0006,ABS(B17/100-Claves!$A$25)<=0.0006)),"✔ Bien",IF(NOT(ISNUMBER(B17)),"✘ Escribe solo el número (sin texto ni %).",IF(OR(ABS(B17-0.17142857142857143)<=0.00051,ABS(B17/100-0.17142857142857143)<=0.00051),"✘ En una condicionada se divide entre el total de la FILA, no entre n.",IF(OR(ABS(B17-0.46153846153846156)<=0.00051,ABS(B17/100-0.46153846153846156)<=0.00051),"✘ Eso es Turno | Satisfacción: has dividido entre el total de la columna.","✘ Revisa el cálculo.")))))
A18: De los "Alta", ¿qué proporción es de Tarde? (Turno | Satisfacción = Alta) | C18: =IF(B18="","",IF(AND(ISNUMBER(B18),OR(ABS(B18-Claves!$A$26)<=0.00051,ABS(B18/100-Claves!$A$26)<=0.00051)),"✔ Bien",IF(NOT(ISNUMBER(B18)),"✘ Escribe solo el número (sin texto ni %).",IF(OR(ABS(B18-0.24)<=0.00051,ABS(B18/100-0.24)<=0.00051),"✘ Eso es la condicionada por fila. Aquí te restringes a la COLUMNA.",IF(OR(ABS(B18-0.08571428571428572)<=0.00051,ABS(B18/100-0.08571428571428572)<=0.00051),"✘ Divide entre el total de la columna, no entre n.","✘ Revisa el cálculo.")))))
A19: ¿Son independientes? (Sí / No) | C19: =IF(B19="","",IF(OR(UPPER(TRIM(B19))="NO"),"✔ Bien",IF(UPPER(TRIM(B19))="SI","✘ Compara fᵢⱼ con fᵢ.×f.ⱼ en todas las casillas (o los % de cada fila).",IF(UPPER(TRIM(B19))="SÍ","✘ Compara fᵢⱼ con fᵢ.×f.ⱼ en todas las casillas (o los % de cada fila).","✘ Revisa la respuesta."))))

Sheet S1_P4
A1: Simulacro 1 · Pregunta 4 (2 puntos)
A2: Formación y productividad | E2: Aciertos: | F2: =SUMPRODUCT(--(LEFT($C$1:$C$32,1)="✔")) | G2: de 9
A4: Celdas azules: datos. Celdas amarillas: tu respuesta (se ponen verdes si está bien y rojas si no).
A6: Horas de formación (X) y Productividad en puntos (Y) de 8 casos.
A7: X | B7: Y
A8: 5 | B8: 62
A9: 8 | B9: 65
A10: 10 | B10: 70
A11: 12 | B11: 71
A12: 15 | B12: 76
A13: 18 | B13: 80
A14: 20 | B14: 79
A15: 25 | B15: 88
A17: Preguntas
A18: Media de X | C18: =IF(B18="","",IF(AND(ISNUMBER(B18),ABS(B18-Claves!$A$28)<=0.014125),"✔ Bien",IF(NOT(ISNUMBER(B18)),"✘ Escribe solo el número (sin texto ni %).","✘ Revisa el cálculo.")))
A19: Media de Y | C19: =IF(B19="","",IF(AND(ISNUMBER(B19),ABS(B19-Claves!$A$29)<=0.073875),"✔ Bien",IF(NOT(ISNUMBER(B19)),"✘ Escribe solo el número (sin texto ni %).","✘ Revisa el cálculo.")))
A20: Covarianza | C20: =IF(B20="","",IF(AND(ISNUMBER(B20),ABS(B20-Claves!$A$30)<=0.049265625),"✔ Bien",IF(NOT(ISNUMBER(B20)),"✘ Escribe solo el número (sin texto ni %).",IF(ABS(B20-56.30357142857143)<=0.05630357142857143,"✘ Has usado COVARIANZA.M (divide entre n−1). En clase se usa COVARIANZA.P.","✘ Revisa el cálculo."))))
A21: Pendiente b (recta de Y sobre X) | C21: =IF(B21="","",IF(AND(ISNUMBER(B21),ABS(B21-Claves!$A$31)<=0.0012677925211097708),"✔ Bien",IF(NOT(ISNUMBER(B21)),"✘ Escribe solo el número (sin texto ni %).",IF(ABS(B21-0.7714705162711035)<=0.0007714705162711036,"✘ Esa es la pendiente de X sobre Y. En PENDIENTE va primero la Y: =PENDIENTE(Y;X).",IF(ABS(B21-7.903074776490386)<=0.007903074776490385,"✘ b = Sxy / Sx² (la VARIANZA de X, no la desviación).","✘ Revisa el cálculo.")))))
A22: Término independiente a | C22: =IF(B22="","",IF(AND(ISNUMBER(B22),ABS(B22-Claves!$A$32)<=0.055967430639324495),"✔ Bien",IF(NOT(ISNUMBER(B22)),"✘ Escribe solo el número (sin texto ni %).",IF(ABS(B22--42.86738438952777)<=0.04286738438952777,"✘ Ese es el de la recta de X sobre Y. Usa =INTERSECCION.EJE(Y;X).","✘ Revisa el cálculo."))))
A23: Coeficiente de correlación r | C23: =IF(B23="","",IF(AND(ISNUMBER(B23),ABS(B23-Claves!$A$33)<=0.0009889714610569907),"✔ Bien",IF(NOT(ISNUMBER(B23)),"✘ Escribe solo el número (sin texto ni %).",IF(ABS(B23-0.9780645507851989)<=0.000978064550785199,"✘ Eso es R². r es la raíz (con el signo de b).","✘ Revisa el cálculo."))))
A24: Coeficiente de determinación R² (decimal) | C24: =IF(B24="","",IF(AND(ISNUMBER(B24),OR(ABS(B24-Claves!$A$34)<=0.000978064550785199,ABS(B24/100-Claves!$A$34)<=0.000978064550785199)),"✔ Bien",IF(NOT(ISNUMBER(B24)),"✘ Escribe solo el número (sin texto ni %).",IF(OR(ABS(B24-0.9889714610569907)<=0.0009889714610569907,ABS(B24/100-0.9889714610569907)<=0.0009889714610569907),"✘ Eso es r. R² es r al cuadrado.","✘ Revisa el cálculo."))))
A25: Predicción de Y para X = 22 | C25: =IF(B25="","",IF(AND(ISNUMBER(B25),ABS(B25-Claves!$A$35)<=0.08385886610373945),"✔ Bien",IF(NOT(ISNUMBER(B25)),"✘ Escribe solo el número (sin texto ni %).",IF(ABS(B25--25.895033031563493)<=0.025895033031563493,"✘ Has usado la recta de X sobre Y.","✘ Revisa el cálculo."))))
A26: % de la variabilidad de Y que NO explica la recta | C26: =IF(B26="","",IF(AND(ISNUMBER(B26),OR(ABS(B26-Claves!$A$36)<=0.00051,ABS(B26/100-Claves!$A$36)<=0.00051)),"✔ Bien",IF(NOT(ISNUMBER(B26)),"✘ Escribe solo el número (sin texto ni %).",IF(OR(ABS(B26-0.9780645507851989)<=0.000978064550785199,ABS(B26/100-0.9780645507851989)<=0.000978064550785199),"✘ Ese es el % que SÍ explica (R²). El no explicado es 1 − R².","✘ Revisa el cálculo."))))

Sheet S1_P5
A1: Simulacro 1 · Pregunta 5 (2 puntos)
A2: Cesta de la compra y salario real | E2: Aciertos: | F2: =SUMPRODUCT(--(LEFT($C$1:$C$32,1)="✔")) | G2: de 6
A4: Celdas azules: datos. Celdas amarillas: tu respuesta (se ponen verdes si está bien y rojas si no).
A6: Cesta de productos: precios y cantidades en el año base (2020) y en 2025.
A7: Producto | B7: p₀ | C7: q₀ | D7: pₜ | E7: qₜ
A8: A | B8: 2 | C8: 50 | D8: 2.4 | E8: 45
A9: B | B9: 5 | C9: 20 | D9: 5.5 | E9: 22
A10: C | B10: 1.5 | C10: 80 | D10: 1.8 | E10: 70
A12: Preguntas
A13: Índice de Laspeyres de precios | C13: =IF(B13="","",IF(AND(ISNUMBER(B13),ABS(B13-Claves!$A$37)<=0.116875),"✔ Bien",IF(NOT(ISNUMBER(B13)),"✘ Escribe solo el número (sin texto ni %).",IF(ABS(B13-116.39344262295081)<=0.11639344262295082,"✘ Ese es Paasche. Laspeyres usa las cantidades del año BASE (q₀).",IF(ABS(B13-85.56149732620321)<=0.08556149732620322,"✘ Está al revés: arriba van los precios de 2025.","✘ Revisa el cálculo.")))))
A14: Índice de Paasche de precios | C14: =IF(B14="","",IF(AND(ISNUMBER(B14),ABS(B14-Claves!$A$38)<=0.11639344262295082),"✔ Bien",IF(NOT(ISNUMBER(B14)),"✘ Escribe solo el número (sin texto ni %).",IF(ABS(B14-116.875)<=0.116875,"✘ Ese es Laspeyres. Paasche usa las cantidades ACTUALES (qₜ).","✘ Revisa el cálculo."))))
A15: Índice de Fisher | C15: =IF(B15="","",IF(AND(ISNUMBER(B15),ABS(B15-Claves!$A$39)<=0.1166339727804784),"✔ Bien",IF(NOT(ISNUMBER(B15)),"✘ Escribe solo el número (sin texto ni %).","✘ Revisa el cálculo.")))
A17: Salario mensual (€) e IPC (2022 = 100):
A18: Año | B18: Salario | C18: IPC
A19: 2022 | B19: 2100 | C19: 100
A20: 2023 | B20: 2200 | C20: 102
A21: 2024 | B21: 2250 | C21: 105.6
A22: 2025 | B22: 2330 | C22: 109.8
A24: Salario real de 2025 en € de 2022 | C24: =IF(B24="","",IF(AND(ISNUMBER(B24),ABS(B24-Claves!$A$40)<=2.122040072859745),"✔ Bien",IF(NOT(ISNUMBER(B24)),"✘ Escribe solo el número (sin texto ni %).",IF(ABS(B24-2558.34)<=2.5583400000000003,"✘ Para deflactar se DIVIDE entre el IPC (× 100).","✘ Revisa el cálculo."))))
A25: Variación nominal 2022-2025 (decimal) | C25: =IF(B25="","",IF(AND(ISNUMBER(B25),OR(ABS(B25-Claves!$A$41)<=0.00010952380952380959,ABS(B25/100-Claves!$A$41)<=0.00010952380952380959)),"✔ Bien",IF(NOT(ISNUMBER(B25)),"✘ Escribe solo el número (sin texto ni %).","✘ Revisa el cálculo.")))
A26: Variación real 2022-2025 (decimal) | C26: =IF(B26="","",IF(AND(ISNUMBER(B26),OR(ABS(B26-Claves!$A$42)<=5.1000000000000006e-05,ABS(B26/100-Claves!$A$42)<=5.1000000000000006e-05)),"✔ Bien",IF(NOT(ISNUMBER(B26)),"✘ Escribe solo el número (sin texto ni %).",IF(OR(ABS(B26-0.011523809523809714)<=5.1000000000000006e-05,ABS(B26/100-0.011523809523809714)<=5.1000000000000006e-05),"✘ Los porcentajes no se restan: compara el salario real con el de 2022.","✘ Revisa el cálculo."))))

Sheet S2_P1
A1: Simulacro 2 · Pregunta 1 (2 puntos)
A2: Hijos por empleado | E2: Aciertos: | F2: =SUMPRODUCT(--(LEFT($C$1:$C$28,1)="✔")) | G2: de 11
A4: Celdas azules: datos. Celdas amarillas: tu respuesta (se ponen verdes si está bien y rojas si no).
A6: Número de hijos de 28 empleados.
A7: Datos | B7: 1 | C7: 0 | D7: 2 | E7: 2 | F7: 1 | G7: 3 | H7: 0 | I7: 1 | J7: 1 | K7: 2
B8: 4 | C8: 0 | D8: 1 | E8: 2 | F8: 1 | G8: 0 | H8: 3 | I8: 1 | J8: 2 | K8: 1
B9: 0 | C9: 2 | D9: 1 | E9: 6 | F9: 1 | G9: 0 | H9: 2 | I9: 1
A11: Preguntas
A12: Tamaño de la muestra (n) | C12: =IF(B12="","",IF(AND(ISNUMBER(B12),ABS(B12-Claves!$A$43)<=0.51),"✔ Bien",IF(NOT(ISNUMBER(B12)),"✘ Escribe solo el número (sin texto ni %).","✘ Revisa el cálculo.")))
A13: Media | C13: =IF(B13="","",IF(AND(ISNUMBER(B13),ABS(B13-Claves!$A$44)<=0.0051),"✔ Bien",IF(NOT(ISNUMBER(B13)),"✘ Escribe solo el número (sin texto ni %).",IF(ABS(B13-2.6666666666666665)<=0.0051,"✘ Has hecho la media de los valores distintos. Cada valor cuenta tantas veces como se repite.","✘ Revisa el cálculo."))))
A14: Mediana | C14: =IF(B14="","",IF(AND(ISNUMBER(B14),ABS(B14-Claves!$A$45)<=0.0051),"✔ Bien",IF(NOT(ISNUMBER(B14)),"✘ Escribe solo el número (sin texto ni %).","✘ Revisa el cálculo.")))
A15: Moda | C15: =IF(B15="","",IF(AND(ISNUMBER(B15),ABS(B15-Claves!$A$46)<=0.51),"✔ Bien",IF(NOT(ISNUMBER(B15)),"✘ Escribe solo el número (sin texto ni %).",IF(ABS(B15-11)<=0.51,"✘ Eso es la frecuencia más alta. La moda es el VALOR que tiene esa frecuencia.","✘ Revisa el cálculo."))))
A16: Primer cuartil (con CUARTIL.INC) | C16: =IF(B16="","",IF(AND(ISNUMBER(B16),ABS(B16-Claves!$A$47)<=0.0051),"✔ Bien",IF(NOT(ISNUMBER(B16)),"✘ Escribe solo el número (sin texto ni %).","✘ Revisa el cálculo.")))
A17: Tercer cuartil (con CUARTIL.INC) | C17: =IF(B17="","",IF(AND(ISNUMBER(B17),ABS(B17-Claves!$A$48)<=0.0051),"✔ Bien",IF(NOT(ISNUMBER(B17)),"✘ Escribe solo el número (sin texto ni %).","✘ Revisa el cálculo.")))
A18: Varianza S² (la de clase) | C18: =IF(B18="","",IF(AND(ISNUMBER(B18),ABS(B18-Claves!$A$49)<=0.0017487244897959183),"✔ Bien",IF(NOT(ISNUMBER(B18)),"✘ Escribe solo el número (sin texto ni %).",IF(ABS(B18-1.8134920634920633)<=0.0018134920634920633,"✘ Has calculado la cuasivarianza (VAR.S). Aquí se pide VAR.P.",IF(ABS(B18-3.892857142857143)<=0.003892857142857143,"✘ Te falta restar la media al cuadrado.","✘ Revisa el cálculo.")))))
A19: Cuasivarianza s² | C19: =IF(B19="","",IF(AND(ISNUMBER(B19),ABS(B19-Claves!$A$50)<=0.0018134920634920633),"✔ Bien",IF(NOT(ISNUMBER(B19)),"✘ Escribe solo el número (sin texto ni %).",IF(ABS(B19-1.7487244897959182)<=0.0017487244897959183,"✘ Esa es la varianza (VAR.P). La cuasivarianza es VAR.S.","✘ Revisa el cálculo."))))
A20: Desviación típica S | C20: =IF(B20="","",IF(AND(ISNUMBER(B20),ABS(B20-Claves!$A$51)<=0.001322393470112401),"✔ Bien",IF(NOT(ISNUMBER(B20)),"✘ Escribe solo el número (sin texto ni %).",IF(ABS(B20-1.3466595945123114)<=0.0013466595945123114,"✘ Has usado DESVEST.S. La desviación típica de clase es DESVEST.P.",IF(ABS(B20-1.7487244897959182)<=0.0017487244897959183,"✘ Eso es la varianza. La desviación típica es su raíz.","✘ Revisa el cálculo.")))))
A21: Coeficiente de variación (en decimal) | C21: =IF(B21="","",IF(AND(ISNUMBER(B21),OR(ABS(B21-Claves!$A$52)<=0.000903097979588957,ABS(B21/100-Claves!$A$52)<=0.000903097979588957)),"✔ Bien",IF(NOT(ISNUMBER(B21)),"✘ Escribe solo el número (sin texto ni %).",IF(OR(ABS(B21-0.9196699669840176)<=0.0009196699669840176,ABS(B21/100-0.9196699669840176)<=0.0009196699669840176),"✘ Usa DESVEST.P en el CV, no DESVEST.S.",IF(OR(ABS(B21-1.107299565054002)<=0.001107299565054002,ABS(B21/100-1.107299565054002)<=0.001107299565054002),"✘ Está al revés: CV = desviación típica ÷ media.","✘ Revisa el cálculo.")))))
A22: Proporción de empleados con más de 1 (en decimal o %) | C22: =IF(B22="","",IF(AND(ISNUMBER(B22),OR(ABS(B22-Claves!$A$53)<=0.00051,ABS(B22/100-Claves!$A$53)<=0.00051)),"✔ Bien",IF(NOT(ISNUMBER(B22)),"✘ Escribe solo el número (sin texto ni %).",IF(OR(ABS(B22-0.7857142857142857)<=0.0007857142857142857,ABS(B22/100-0.7857142857142857)<=0.0007857142857142857),"✘ ""Más de 1"" no incluye el 1.",IF(OR(ABS(B22-11)<=0.011,ABS(B22/100-11)<=0.011),"✘ Eso es cuántos son. Piden la proporción: divide entre n.","✘ Revisa el cálculo.")))))

Sheet S2_P2
A1: Simulacro 2 · Pregunta 2 (2 puntos)
A2: Tiempo de desplazamiento al trabajo | E2: Aciertos: | F2: =SUMPRODUCT(--(LEFT($C$1:$C$28,1)="✔")) | G2: de 8
A4: Celdas azules: datos. Celdas amarillas: tu respuesta (se ponen verdes si está bien y rojas si no).
A6: Minutos de desplazamiento al trabajo de 100 personas.
A7: Intervalo | B7: nᵢ
A8: [0, 10] | B8: 14
A9: (10, 20] | B9: 26
A10: (20, 30] | B10: 31
A11: (30, 45] | B11: 19
A12: (45, 90] | B12: 10
A14: Preguntas
A15: n (total) | C15: =IF(B15="","",IF(AND(ISNUMBER(B15),ABS(B15-Claves!$A$54)<=0.51),"✔ Bien",IF(NOT(ISNUMBER(B15)),"✘ Escribe solo el número (sin texto ni %).","✘ Revisa el cálculo.")))
A16: Media | C16: =IF(B16="","",IF(AND(ISNUMBER(B16),ABS(B16-Claves!$A$55)<=0.026225000000000002),"✔ Bien",IF(NOT(ISNUMBER(B16)),"✘ Escribe solo el número (sin texto ni %).",IF(ABS(B16-30)<=0.03,"✘ Has promediado las marcas sin multiplicar por las frecuencias.","✘ Revisa el cálculo."))))
A17: Varianza S² | C17: =IF(B17="","",IF(AND(ISNUMBER(B17),ABS(B17-Claves!$A$56)<=0.2908118749999999),"✔ Bien",IF(NOT(ISNUMBER(B17)),"✘ Escribe solo el número (sin texto ni %).",IF(ABS(B17-978.5625)<=0.9785625,"✘ Te falta restar la media al cuadrado.",IF(ABS(B17-293.74936868686854)<=0.2937493686868685,"✘ Esa es la cuasivarianza (divide entre n−1). Aquí se pide la varianza.","✘ Revisa el cálculo.")))))
A18: Desviación típica S | C18: =IF(B18="","",IF(AND(ISNUMBER(B18),ABS(B18-Claves!$A$57)<=0.017053207176364212),"✔ Bien",IF(NOT(ISNUMBER(B18)),"✘ Escribe solo el número (sin texto ni %).","✘ Revisa el cálculo.")))
A19: Coeficiente de variación (decimal) | C19: =IF(B19="","",IF(AND(ISNUMBER(B19),OR(ABS(B19-Claves!$A$58)<=0.0006502652879452511,ABS(B19/100-Claves!$A$58)<=0.0006502652879452511)),"✔ Bien",IF(NOT(ISNUMBER(B19)),"✘ Escribe solo el número (sin texto ni %).","✘ Revisa el cálculo.")))
A20: Moda (fórmula de intervalos) | C20: =IF(B20="","",IF(AND(ISNUMBER(B20),ABS(B20-Claves!$A$59)<=0.02214285714285714),"✔ Bien",IF(NOT(ISNUMBER(B20)),"✘ Escribe solo el número (sin texto ni %).",IF(ABS(B20-22.941176470588236)<=0.022941176470588236,"✘ Has usado las frecuencias. Con amplitudes distintas, el intervalo modal se elige por la DENSIDAD.","✘ Revisa el cálculo."))))
A21: Mediana | C21: =IF(B21="","",IF(AND(ISNUMBER(B21),ABS(B21-Claves!$A$60)<=0.023225806451612905),"✔ Bien",IF(NOT(ISNUMBER(B21)),"✘ Escribe solo el número (sin texto ni %).",IF(ABS(B21-25)<=0.025,"✘ Eso es la marca del intervalo. Aplica la fórmula: Linf + (n/2 − Nᵢ₋₁)/nᵢ · aᵢ.","✘ Revisa el cálculo."))))
A22: ¿A partir de qué valor se está en el 25 % con valores más altos? | C22: =IF(B22="","",IF(AND(ISNUMBER(B22),ABS(B22-Claves!$A$61)<=0.0331578947368421),"✔ Bien",IF(NOT(ISNUMBER(B22)),"✘ Escribe solo el número (sin texto ni %).",IF(ABS(B22-14.23076923076923)<=0.01423076923076923,"✘ Ese es el percentil 25. ""El 25 % de arriba"" empieza en el percentil 75.","✘ Revisa el cálculo."))))

Sheet S2_P3
A1: Simulacro 2 · Pregunta 3 (2 puntos)
A2: Salarios por sexo | E2: Aciertos: | F2: =SUMPRODUCT(--(LEFT($C$1:$C$28,1)="✔")) | G2: de 9
A4: Celdas azules: datos. Celdas amarillas: tu respuesta (se ponen verdes si está bien y rojas si no).
A6: Salario medio por grupo (€). Te dan el tamaño, la media y la DESVIACIÓN TÍPICA de cada grupo.
A7: Grupo | B7: Tamaño T | C7: Media | D7: Desv. típica
A8: Mujeres | B8: 60 | C8: 1980 | D8: 310
A9: Hombres | B9: 90 | C9: 2240 | D9: 420
A11: Preguntas
A12: ¿Qué grupo es más homogéneo? (escribe el nombre) | C12: =IF(B12="","",IF(OR(UPPER(TRIM(B12))="MUJERES"),"✔ Bien","✘ Revisa la respuesta."))
A13: Media global | C13: =IF(B13="","",IF(AND(ISNUMBER(B13),ABS(B13-Claves!$A$63)<=2.136),"✔ Bien",IF(NOT(ISNUMBER(B13)),"✘ Escribe solo el número (sin texto ni %).",IF(ABS(B13-2110)<=2.11,"✘ Has hecho la media de las medias sin ponderar por el tamaño de cada grupo.","✘ Revisa el cálculo."))))
A14: Varianza dentro de los grupos | C14: =IF(B14="","",IF(AND(ISNUMBER(B14),ABS(B14-Claves!$A$64)<=144.28),"✔ Bien",IF(NOT(ISNUMBER(B14)),"✘ Escribe solo el número (sin texto ni %).",IF(ABS(B14-376)<=0.376,"✘ Has usado las desviaciones típicas. Hay que elevarlas al cuadrado (varianzas).","✘ Revisa el cálculo."))))
A15: Varianza entre los grupos | C15: =IF(B15="","",IF(AND(ISNUMBER(B15),ABS(B15-Claves!$A$65)<=16.224),"✔ Bien",IF(NOT(ISNUMBER(B15)),"✘ Escribe solo el número (sin texto ni %).","✘ Revisa el cálculo.")))
A16: Varianza total | C16: =IF(B16="","",IF(AND(ISNUMBER(B16),ABS(B16-Claves!$A$66)<=160.504),"✔ Bien",IF(NOT(ISNUMBER(B16)),"✘ Escribe solo el número (sin texto ni %).","✘ Revisa el cálculo.")))
A17: Desviación típica total | C17: =IF(B17="","",IF(AND(ISNUMBER(B17),ABS(B17-Claves!$A$67)<=0.40062950465486186),"✔ Bien",IF(NOT(ISNUMBER(B17)),"✘ Escribe solo el número (sin texto ni %).",IF(ABS(B17-160504)<=160.504,"✘ Eso es la varianza. Haz la raíz cuadrada.","✘ Revisa el cálculo."))))
A18: % de la variabilidad debido a las diferencias entre grupos | C18: =IF(B18="","",IF(AND(ISNUMBER(B18),OR(ABS(B18-Claves!$A$68)<=0.00051,ABS(B18/100-Claves!$A$68)<=0.00051)),"✔ Bien",IF(NOT(ISNUMBER(B18)),"✘ Escribe solo el número (sin texto ni %).",IF(OR(ABS(B18-0.8989184070178936)<=0.0008989184070178936,ABS(B18/100-0.8989184070178936)<=0.0008989184070178936),"✘ Ese es el % de dentro de los grupos.","✘ Revisa el cálculo."))))
A20: Si todos los salarios suben un 2 % y además 30 €:
A21: Nueva media global | C21: =IF(B21="","",IF(AND(ISNUMBER(B21),ABS(B21-Claves!$A$69)<=2.2087200000000005),"✔ Bien",IF(NOT(ISNUMBER(B21)),"✘ Escribe solo el número (sin texto ni %).","✘ Revisa el cálculo.")))
A22: Nueva varianza total | C22: =IF(B22="","",IF(AND(ISNUMBER(B22),ABS(B22-Claves!$A$70)<=166.98836160000002),"✔ Bien",IF(NOT(ISNUMBER(B22)),"✘ Escribe solo el número (sin texto ni %).",IF(ABS(B22-163714.08000000002)<=163.71408000000002,"✘ La varianza se multiplica por a² (no por a).","✘ Revisa el cálculo."))))

Sheet S2_P4
A1: Simulacro 2 · Pregunta 4 (2 puntos)
A2: Absentismo y satisfacción | E2: Aciertos: | F2: =SUMPRODUCT(--(LEFT($C$1:$C$33,1)="✔")) | G2: de 9
A4: Celdas azules: datos. Celdas amarillas: tu respuesta (se ponen verdes si está bien y rojas si no).
A6: Días de ausencia al año (X) y Satisfacción 0-10 (Y) de 9 casos.
A7: X | B7: Y
A8: 2 | B8: 8.4
A9: 3 | B9: 8.1
A10: 5 | B10: 7.2
A11: 6 | B11: 7.4
A12: 8 | B12: 6.1
A13: 9 | B13: 6.3
A14: 11 | B14: 5
A15: 12 | B15: 5.2
A16: 14 | B16: 4.1
A18: Preguntas
A19: Media de X | C19: =IF(B19="","",IF(AND(ISNUMBER(B19),ABS(B19-Claves!$A$71)<=0.0077777777777777776),"✔ Bien",IF(NOT(ISNUMBER(B19)),"✘ Escribe solo el número (sin texto ni %).","✘ Revisa el cálculo.")))
A20: Media de Y | C20: =IF(B20="","",IF(AND(ISNUMBER(B20),ABS(B20-Claves!$A$72)<=0.006422222222222222),"✔ Bien",IF(NOT(ISNUMBER(B20)),"✘ Escribe solo el número (sin texto ni %).","✘ Revisa el cálculo.")))
A21: Covarianza | C21: =IF(B21="","",IF(AND(ISNUMBER(B21),ABS(B21-Claves!$A$73)<=0.005306172839506182),"✔ Bien",IF(NOT(ISNUMBER(B21)),"✘ Escribe solo el número (sin texto ni %).",IF(ABS(B21--5.969444444444455)<=0.005969444444444455,"✘ Has usado COVARIANZA.M (divide entre n−1). En clase se usa COVARIANZA.P.","✘ Revisa el cálculo."))))
A22: Pendiente b (recta de Y sobre X) | C22: =IF(B22="","",IF(AND(ISNUMBER(B22),ABS(B22-Claves!$A$74)<=0.00051),"✔ Bien",IF(NOT(ISNUMBER(B22)),"✘ Escribe solo el número (sin texto ni %).",IF(ABS(B22--2.757956878850107)<=0.002757956878850107,"✘ Esa es la pendiente de X sobre Y. En PENDIENTE va primero la Y: =PENDIENTE(Y;X).",IF(ABS(B22--1.3672375782672277)<=0.0013672375782672278,"✘ b = Sxy / Sx² (la VARIANZA de X, no la desviación).","✘ Revisa el cálculo.")))))
A23: Término independiente a | C23: =IF(B23="","",IF(AND(ISNUMBER(B23),ABS(B23-Claves!$A$75)<=0.009162295081967219),"✔ Bien",IF(NOT(ISNUMBER(B23)),"✘ Escribe solo el número (sin texto ni %).",IF(ABS(B23-25.489989733059577)<=0.025489989733059576,"✘ Ese es el de la recta de X sobre Y. Usa =INTERSECCION.EJE(Y;X).","✘ Revisa el cálculo."))))
A24: Coeficiente de correlación r | C24: =IF(B24="","",IF(AND(ISNUMBER(B24),ABS(B24-Claves!$A$76)<=0.0009857051509942207),"✔ Bien",IF(NOT(ISNUMBER(B24)),"✘ Escribe solo el número (sin texto ni %).",IF(ABS(B24-0.9857051509942207)<=0.0009857051509942207,"✘ Fíjate en el signo: r tiene el mismo signo que la pendiente.","✘ Revisa el cálculo."))))
A25: Coeficiente de determinación R² (decimal) | C25: =IF(B25="","",IF(AND(ISNUMBER(B25),OR(ABS(B25-Claves!$A$77)<=0.0009716146446965395,ABS(B25/100-Claves!$A$77)<=0.0009716146446965395)),"✔ Bien",IF(NOT(ISNUMBER(B25)),"✘ Escribe solo el número (sin texto ni %).",IF(OR(ABS(B25--0.9857051509942207)<=0.0009857051509942207,ABS(B25/100--0.9857051509942207)<=0.0009857051509942207),"✘ Eso es r. R² es r al cuadrado.","✘ Revisa el cálculo."))))
A26: Predicción de Y para X = 10 | C26: =IF(B26="","",IF(AND(ISNUMBER(B26),ABS(B26-Claves!$A$78)<=0.005639344262295082),"✔ Bien",IF(NOT(ISNUMBER(B26)),"✘ Escribe solo el número (sin texto ni %).",IF(ABS(B26--2.0895790554414937)<=0.0051,"✘ Has usado la recta de X sobre Y.","✘ Revisa el cálculo."))))
A27: % de la variabilidad de Y que NO explica la recta | C27: =IF(B27="","",IF(AND(ISNUMBER(B27),OR(ABS(B27-Claves!$A$79)<=0.00051,ABS(B27/100-Claves!$A$79)<=0.00051)),"✔ Bien",IF(NOT(ISNUMBER(B27)),"✘ Escribe solo el número (sin texto ni %).",IF(OR(ABS(B27-0.9716146446965395)<=0.0009716146446965395,ABS(B27/100-0.9716146446965395)<=0.0009716146446965395),"✘ Ese es el % que SÍ explica (R²). El no explicado es 1 − R².","✘ Revisa el cálculo."))))

Sheet S2_P5
A1: Simulacro 2 · Pregunta 5 (2 puntos)
A2: Índices y tasas | E2: Aciertos: | F2: =SUMPRODUCT(--(LEFT($C$1:$C$24,1)="✔")) | G2: de 2
A4: Celdas azules: datos. Celdas amarillas: tu respuesta (se ponen verdes si está bien y rojas si no).
A6: Ventas anuales de una empresa (miles de €).
A7: 💡 Índice base 2020 = valor/valor 2020 × 100. Tasa = valor/anterior − 1. Tasa media anual = (1 + tasa total)^(1/nº de años) − 1.
A8: Año | B8: Ventas | C8: Índice base 2020 | D8: Tasa vs año anterior | E8: Índice base 2022
A9: Pista → | C9: ej. =B/B$2020*100 | D9: ej. =B/B anterior−1 | E9: ej. =índice/índice 2022*100
A10: 2020 | B10: 1250
A11: 2021 | B11: 1300
A12: 2022 | B12: 1365
A13: 2023 | B13: 1350
A14: 2024 | B14: 1420
A16: Preguntas
A17: Tasa de variación total 2020-2024 (decimal) | C17: =IF(B17="","",IF(AND(ISNUMBER(B17),OR(ABS(B17-Claves!$A$95)<=0.0001359999999999999,ABS(B17/100-Claves!$A$95)<=0.0001359999999999999)),"✔ Bien",IF(NOT(ISNUMBER(B17)),"✘ Escribe solo el número (sin texto ni %).","✘ Revisa el cálculo.")))
A18: Tasa media anual 2020-2024 (decimal) | C18: =IF(B18="","",IF(AND(ISNUMBER(B18),OR(ABS(B18-Claves!$A$96)<=5.1000000000000006e-05,ABS(B18/100-Claves!$A$96)<=5.1000000000000006e-05)),"✔ Bien",IF(NOT(ISNUMBER(B18)),"✘ Escribe solo el número (sin texto ni %).",IF(OR(ABS(B18-0.032715710215710236)<=5.1000000000000006e-05,ABS(B18/100-0.032715710215710236)<=5.1000000000000006e-05),"✘ Has hecho la media aritmética de las tasas. Hay que usar la media geométrica: (1+T)^(1/4) − 1.",IF(OR(ABS(B18-0.033999999999999975)<=5.1000000000000006e-05,ABS(B18/100-0.033999999999999975)<=5.1000000000000006e-05),"✘ No se divide la tasa entre 4: (1+T)^(1/4) − 1.",IF(OR(ABS(B18-0.025830639140963285)<=5.1000000000000006e-05,ABS(B18/100-0.025830639140963285)<=5.1000000000000006e-05),"✘ De 2020 a 2024 hay 4 años, no 5.","✘ Revisa el cálculo."))))))

Sheet Claves
A1: 25
A2: 1.56
A3: 1
A4: 0
A5: 0
A6: 2
A7: 4.0864
A8: 4.2566667
A9: 2.0214846
A10: 1.2958235
A11: 0.2
A12: 9
... A26: 0.33333333
A27: No
A28: 14.125
A29: 73.875
A30: 49.265625
A31: 1.2677925
A32: 55.967431
A33: 0.98897146
A34: 0.97806455
A35: 83.858866
A36: 0.021935449
A37: 116.875
A38: 116.39344
A39: 116.63397
... A61: 33.157895
A62: Mujeres
A63: 2136
A64: 144280
A65: 16224
A66: 160504
A67: 400.6295
A68: 0.10108159
A69: 2208.72
A70: 166988.36
A71: 7.7777778
A72: 6.4222222
A73: -5.3061728
A74: -0.35229508
...
