Workbook

Sheet Inicio
B2: Prácticas autocorregidas
B4: Cada tipo de ejercicio tiene tres niveles, con datos distintos en cada uno:
B5: Nivel 1 · Con guía: la tabla de trabajo ya tiene las columnas y una fila de pistas.
B6: Nivel 2 · Con cabeceras: tienes las columnas, pero sin pistas.
B7: Nivel 3 · Sin ayuda: solo los datos y las preguntas, como en el examen.
B8: Escribe tus resultados en las celdas amarillas. Se ponen verdes si están bien y rojas si no;
B9: al lado aparece una pista cuando el error es uno de los típicos.
B10: Puedes hacer los cálculos donde quieras de la hoja (a la derecha hay sitio) y escribir solo el resultado,
B11: o poner directamente la fórmula en la celda amarilla. Los decimales con coma, como siempre.
B12: Las proporciones puedes darlas en decimal (0,25) o en porcentaje (25).
B14: Hoja | C14: Ejercicio | D14: Nivel | E14: Aciertos
B15: 1_Discreta_N1 | C15: Variable discreta: tabla y medidas | D15: Con guía | E15: ='1_Discreta_N1'!$F$2&" de 11"
B16: 1_Discreta_N2 | C16: Variable discreta: tabla y medidas | D16: Con cabeceras | E16: ='1_Discreta_N2'!$F$2&" de 11"
B17: 1_Discreta_N3 | C17: Variable discreta: tabla y medidas | D17: Sin ayuda | E17: ='1_Discreta_N3'!$F$2&" de 11"
B18: 2_Intervalos_N1 | C18: Datos en intervalos (amplitudes distintas) | D18: Con guía | E18: ='2_Intervalos_N1'!$F$2&" de 8"
B19: 2_Intervalos_N2 | C19: Datos en intervalos (amplitudes distintas) | D19: Con cabeceras | E19: ='2_Intervalos_N2'!$F$2&" de 8"
B20: 2_Intervalos_N3 | C20: Datos en intervalos (amplitudes distintas) | D20: Sin ayuda | E20: ='2_Intervalos_N3'!$F$2&" de 8"
B21: 3_Grupos_N1 | C21: Varianza dentro y entre grupos + cambios de escala | D21: Con guía | E21: ='3_Grupos_N1'!$F$2&" de 9"
B22: 3_Grupos_N2 | C22: Varianza dentro y entre grupos + cambios de escala | D22: Con cabeceras | E22: ='3_Grupos_N2'!$F$2&" de 9"
B23: 3_Grupos_N3 | C23: Varianza dentro y entre grupos + cambios de escala | D23: Sin ayuda | E23: ='3_Grupos_N3'!$F$2&" de 9"
B24: 4_Contingencia_N1 | C24: Tabla de doble entrada e independencia | D24: Con guía | E24: ='4_Contingencia_N1'!$F$2&" de 7"
B25: 4_Contingencia_N2 | C25: Tabla de doble entrada e independencia | D25: Con cabeceras | E25: ='4_Contingencia_N2'!$F$2&" de 7"
B26: 4_Contingencia_N3 | C26: Tabla de doble entrada e independencia | D26: Sin ayuda | E26: ='4_Contingencia_N3'!$F$2&" de 7"
B27: 5_Regresion_N1 | C27: Regresión con datos | D27: Con guía | E27: ='5_Regresion_N1'!$F$2&" de 9"
B28: 5_Regresion_N2 | C28: Regresión con datos | D28: Con cabeceras | E28: ='5_Regresion_N2'!$F$2&" de 9"
B29: 5_Regresion_N3 | C29: Regresión con datos | D29: Sin ayuda | E29: ='5_Regresion_N3'!$F$2&" de 9"
B30: 6_Reg_resumen_N1 | C30: Regresión a partir de resúmenes | D30: Con guía | E30: ='6_Reg_resumen_N1'!$F$2&" de 5"
B31: 6_Reg_resumen_N2 | C31: Regresión a partir de resúmenes | D31: Con cabeceras | E31: ='6_Reg_resumen_N2'!$F$2&" de 5"
B32: 6_Reg_resumen_N3 | C32: Regresión a partir de resúmenes | D32: Sin ayuda | E32: ='6_Reg_resumen_N3'!$F$2&" de 5"
B33: 7_Indices_N1 | C33: Índices y tasas | D33: Con guía | E33: ='7_Indices_N1'!$F$2&" de 2"
B34: 7_Indices_N2 | C34: Índices y tasas | D34: Con cabeceras | E34: ='7_Indices_N2'!$F$2&" de 3"
B35: 7_Indices_N3 | C35: Índices y tasas | D35: Sin ayuda | E35: ='7_Indices_N3'!$F$2&" de 4"
B36: 8_Laspeyres_IPC_N1 | C36: Laspeyres, Paasche y deflactar | D36: Con guía | E36: ='8_Laspeyres_IPC_N1'!$F$2&" de 6"
B37: 8_Laspeyres_IPC_N2 | C37: Laspeyres, Paasche y deflactar | D37: Con cabeceras | E37: ='8_Laspeyres_IPC_N2'!$F$2&" de 6"
B38: 8_Laspeyres_IPC_N3 | C38: Laspeyres, Paasche y deflactar | D38: Sin ayuda | E38: ='8_Laspeyres_IPC_N3'!$F$2&" de 6"

Sheet 1_Discreta_N1
A1: Variable discreta: tabla y medidas · Nivel 1 · Con guía
E2: Aciertos: | F2: =SUMPRODUCT(--(LEFT($C$1:$C$38,1)="✔")) | G2: de 11
A3: Celdas azules: datos. Celdas amarillas: tu respuesta (se ponen verdes si está bien y rojas si no).
A5: Número de días de teletrabajo a la semana de 30 empleados.
A6: Datos | B6: 0 | C6: 1 | D6: 2 | E6: 0 | F6: 0 | G6: 4 | H6: 0 | I6: 0 | J6: 4 | K6: 2
B7: 1 | C7: 1 | D7: 2 | E7: 0 | F7: 0 | G7: 3 | H7: 2 | I7: 1 | J7: 3 | K7: 1
B8: 5 | C8: 0 | D8: 1 | E8: 1 | F8: 1 | G8: 2 | H8: 0 | I8: 3 | J8: 3 | K8: 0
A10: Paso 1 · Tabla de frecuencias
A11: 💡 Escribe en la fila de pistas lo que pondrías en la primera fila. Usa CONTAR.SI sobre los datos de arriba (fíjalos con $).
A12: xᵢ | B12: nᵢ | C12: fᵢ | D12: Nᵢ | E12: xᵢ·nᵢ | F12: xᵢ²·nᵢ
A13: Pista → | B13: ej. =CONTAR.SI(datos;A…) | C13: ej. =nᵢ / n | D13: ej. =Nᵢ₋₁ + nᵢ | E13: ej. =xᵢ*nᵢ | F13: ej. =xᵢ^2*nᵢ
A14: 0
A15: 1
A16: 2
A17: 3
A18: 4
A19: 5
A21: Paso 2 · Medidas
A22: Tamaño de la muestra (n) | C22: =IF(B22="","",IF(AND(ISNUMBER(B22),ABS(B22-Claves!$A$31)<=0.51),"✔ Bien",IF(NOT(ISNUMBER(B22)),"✘ Escribe solo el número (sin texto ni %).","✘ Revisa el cálculo.")))
A23: Media | C23: =IF(B23="","",IF(AND(ISNUMBER(B23),ABS(B23-Claves!$A$32)<=0.0051),"✔ Bien",IF(NOT(ISNUMBER(B23)),"✘ Escribe solo el número (sin texto ni %).",IF(ABS(B23-2.5)<=0.0051,"✘ Has hecho la media de los valores distintos. Cada valor cuenta tantas veces como se repite.","✘ Revisa el cálculo."))))
A24: Mediana | C24: =IF(B24="","",IF(AND(ISNUMBER(B24),ABS(B24-Claves!$A$33)<=0.0051),"✔ Bien",IF(NOT(ISNUMBER(B24)),"✘ Escribe solo el número (sin texto ni %).","✘ Revisa el cálculo.")))
A25: Moda | C25: =IF(B25="","",IF(AND(ISNUMBER(B25),ABS(B25-Claves!$A$34)<=0.51),"✔ Bien",IF(NOT(ISNUMBER(B25)),"✘ Escribe solo el número (sin texto ni %).",IF(ABS(B25-10)<=0.51,"✘ Eso es la frecuencia más alta. La moda es el VALOR que tiene esa frecuencia.","✘ Revisa el cálculo."))))
A26: Primer cuartil (con CUARTIL.INC) | C26: =IF(B26="","",IF(AND(ISNUMBER(B26),ABS(B26-Claves!$A$35)<=0.0051),"✔ Bien",IF(NOT(ISNUMBER(B26)),"✘ Escribe solo el número (sin texto ni %).","✘ Revisa el cálculo.")))
A27: Tercer cuartil (con CUARTIL.INC) | C27: =IF(B27="","",IF(AND(ISNUMBER(B27),ABS(B27-Claves!$A$36)<=0.0051),"✔ Bien",IF(NOT(ISNUMBER(B27)),"✘ Escribe solo el número (sin texto ni %).","✘ Revisa el cálculo.")))
A28: Varianza S² (la de clase) | C28: =IF(B28="","",IF(AND(ISNUMBER(B28),ABS(B28-Claves!$A$37)<=0.0019788888888888885),"✔ Bien",IF(NOT(ISNUMBER(B28)),"✘ Escribe solo el número (sin texto ni %).",IF(ABS(B28-2.047126436781609)<=0.002047126436781609,"✘ Has calculado la cuasivarianza (VAR.S). Aquí se pide VAR.P.",IF(ABS(B28-4.033333333333333)<=0.004033333333333333,"✘ Te falta restar la media al cuadrado.","✘ Revisa el cálculo.")))))
A29: Cuasivarianza s² | C29: =IF(B29="","",IF(AND(ISNUMBER(B29),ABS(B29-Claves!$A$38)<=0.002047126436781609),"✔ Bien",IF(NOT(ISNUMBER(B29)),"✘ Escribe solo el número (sin texto ni %).",IF(ABS(B29-1.9788888888888887)<=0.0019788888888888885,"✘ Esa es la varianza (VAR.P). La cuasivarianza es VAR.S.","✘ Revisa el cálculo."))))
A30: Desviación típica S | C30: =IF(B30="","",IF(AND(ISNUMBER(B30),ABS(B30-Claves!$A$39)<=0.0014067298564006128),"✔ Bien",IF(NOT(ISNUMBER(B30)),"✘ Escribe solo el número (sin texto ni %).",IF(ABS(B30-1.4307782626184986)<=0.0014307782626184987,"✘ Has usado DESVEST.S. La desviación típica de clase es DESVEST.P.",IF(ABS(B30-1.9788888888888887)<=0.0019788888888888885,"✘ Eso es la varianza. La desviación típica es su raíz.","✘ Revisa el cálculo.")))))
A31: Coeficiente de variación (en decimal) | C31: =IF(B31="","",IF(AND(ISNUMBER(B31),OR(ABS(B31-Claves!$A$40)<=0.000981439434698102,ABS(B31/100-Claves!$A$40)<=0.000981439434698102)),"✔ Bien",IF(NOT(ISNUMBER(B31)),"✘ Escribe solo el número (sin texto ni %).",IF(OR(ABS(B31-0.9982173925245339)<=0.000998217392524534,ABS(B31/100-0.9982173925245339)<=0.000998217392524534),"✘ Usa DESVEST.P en el CV, no DESVEST.S.",IF(OR(ABS(B31-1.018911574821331)<=0.001018911574821331,ABS(B31/100-1.018911574821331)<=0.001018911574821331),"✘ Está al revés: CV = desviación típica ÷ media.","✘ Revisa el cálculo.")))))
A32: Proporción de empleados con más de 2 (en decimal o %) | C32: =IF(B32="","",IF(AND(ISNUMBER(B32),OR(ABS(B32-Claves!$A$41)<=0.00051,ABS(B32/100-Claves!$A$41)<=0.00051)),"✔ Bien",IF(NOT(ISNUMBER(B32)),"✘ Escribe solo el número (sin texto ni %).",IF(OR(ABS(B32-0.4)<=0.00051,ABS(B32/100-0.4)<=0.00051),"✘ ""Más de 2"" no incluye el 2.",IF(OR(ABS(B32-7)<=0.007,ABS(B32/100-7)<=0.007),"✘ Eso es cuántos son. Piden la proporción: divide entre n.","✘ Revisa el cálculo.")))))

Sheet 1_Discreta_N2
A1: Variable discreta: tabla y medidas · Nivel 2 · Con cabeceras
E2: Aciertos: | F2: =SUMPRODUCT(--(LEFT($C$1:$C$35,1)="✔")) | G2: de 11
A3: Celdas azules: datos. Celdas amarillas: tu respuesta (se ponen verdes si está bien y rojas si no).
A5: Número de días de teletrabajo a la semana de 30 empleados.
A6: Datos | B6: 1 | C6: 4 | D6: 1 | E6: 0 | F6: 1 | G6: 1 | H6: 2 | I6: 0 | J6: 4 | K6: 3
B7: 0 | C7: 2 | D7: 0 | E7: 1 | F7: 1 | G7: 1 | H7: 1 | I7: 4 | J7: 1 | K7: 1
B8: 2 | C8: 4 | D8: 4 | E8: 4 | F8: 0 | G8: 4 | H8: 2 | I8: 3 | J8: 1 | K8: 1
A10: Paso 1 · Tabla de frecuencias
A11: xᵢ | B11: nᵢ | C11: fᵢ | D11: Nᵢ | E11: xᵢ·nᵢ | F11: xᵢ²·nᵢ
A12: 0
A13: 1
A14: 2
A15: 3
A16: 4
A18: Paso 2 · Medidas
A19: Tamaño de la muestra (n) | C19: =IF(B19="","",IF(AND(ISNUMBER(B19),ABS(B19-Claves!$A$67)<=0.51),"✔ Bien",IF(NOT(ISNUMBER(B19)),"✘ Escribe solo el número (sin texto ni %).","✘ Revisa el cálculo.")))
A20: Media | C20: =IF(B20="","",IF(AND(ISNUMBER(B20),ABS(B20-Claves!$A$68)<=0.0051),"✔ Bien",IF(NOT(ISNUMBER(B20)),"✘ Escribe solo el número (sin texto ni %).",IF(ABS(B20-2)<=0.0051,"✘ Has hecho la media de los valores distintos. Cada valor cuenta tantas veces como se repite.","✘ Revisa el cálculo."))))
A21: Mediana | C21: =IF(B21="","",IF(AND(ISNUMBER(B21),ABS(B21-Claves!$A$69)<=0.0051),"✔ Bien",IF(NOT(ISNUMBER(B21)),"✘ Escribe solo el número (sin texto ni %).","✘ Revisa el cálculo.")))
A22: Moda | C22: =IF(B22="","",IF(AND(ISNUMBER(B22),ABS(B22-Claves!$A$70)<=0.51),"✔ Bien",IF(NOT(ISNUMBER(B22)),"✘ Escribe solo el número (sin texto ni %).",IF(ABS(B22-12)<=0.51,"✘ Eso es la frecuencia más alta. La moda es el VALOR que tiene esa frecuencia.","✘ Revisa el cálculo."))))
A23: Primer cuartil (con CUARTIL.INC) | C23: =IF(B23="","",IF(AND(ISNUMBER(B23),ABS(B23-Claves!$A$71)<=0.0051),"✔ Bien",IF(NOT(ISNUMBER(B23)),"✘ Escribe solo el número (sin texto ni %).","✘ Revisa el cálculo.")))
A24: Tercer cuartil (con CUARTIL.INC) | C24: =IF(B24="","",IF(AND(ISNUMBER(B24),ABS(B24-Claves!$A$72)<=0.0051),"✔ Bien",IF(NOT(ISNUMBER(B24)),"✘ Escribe solo el número (sin texto ni %).","✘ Revisa el cálculo.")))
A25: Varianza S² (la de clase) | C25: =IF(B25="","",IF(AND(ISNUMBER(B25),ABS(B25-Claves!$A$73)<=0.002026666666666667),"✔ Bien",IF(NOT(ISNUMBER(B25)),"✘ Escribe solo el número (sin texto ni %).",IF(ABS(B25-2.0965517241379312)<=0.0020965517241379314,"✘ Has calculado la cuasivarianza (VAR.S). Aquí se pide VAR.P.",IF(ABS(B25-5.266666666666667)<=0.005266666666666667,"✘ Te falta restar la media al cuadrado.","✘ Revisa el cálculo.")))))
A26: Cuasivarianza s² | C26: =IF(B26="","",IF(AND(ISNUMBER(B26),ABS(B26-Claves!$A$74)<=0.0020965517241379314),"✔ Bien",IF(NOT(ISNUMBER(B26)),"✘ Escribe solo el número (sin texto ni %).",IF(ABS(B26-2.026666666666667)<=0.002026666666666667,"✘ Esa es la varianza (VAR.P). La cuasivarianza es VAR.S.","✘ Revisa el cálculo."))))
A27: Desviación típica S | C27: =IF(B27="","",IF(AND(ISNUMBER(B27),ABS(B27-Claves!$A$75)<=0.0014236104336041748),"✔ Bien",IF(NOT(ISNUMBER(B27)),"✘ Escribe solo el número (sin texto ni %).",IF(ABS(B27-1.4479474176011817)<=0.0014479474176011817,"✘ Has usado DESVEST.S. La desviación típica de clase es DESVEST.P.",IF(ABS(B27-2.026666666666667)<=0.002026666666666667,"✘ Eso es la varianza. La desviación típica es su raíz.","✘ Revisa el cálculo.")))))
A28: Coeficiente de variación (en decimal) | C28: =IF(B28="","",IF(AND(ISNUMBER(B28),OR(ABS(B28-Claves!$A$76)<=0.0007908946853356527,ABS(B28/100-Claves!$A$76)<=0.0007908946853356527)),"✔ Bien",IF(NOT(ISNUMBER(B28)),"✘ Escribe solo el número (sin texto ni %).",IF(OR(ABS(B28-0.8044152320006565)<=0.0008044152320006565,ABS(B28/100-0.8044152320006565)<=0.0008044152320006565),"✘ Usa DESVEST.P en el CV, no DESVEST.S.",IF(OR(ABS(B28-1.2643908456352868)<=0.0012643908456352868,ABS(B28/100-1.2643908456352868)<=0.0012643908456352868),"✘ Está al revés: CV = desviación típica ÷ media.","✘ Revisa el cálculo.")))))
A29: Proporción de empleados con más de 2 (en decimal o %) | C29: =IF(B29="","",IF(AND(ISNUMBER(B29),OR(ABS(B29-Claves!$A$77)<=0.00051,ABS(B29/100-Claves!$A$77)<=0.00051)),"✔ Bien",IF(NOT(ISNUMBER(B29)),"✘ Escribe solo el número (sin texto ni %).",IF(OR(ABS(B29-0.43333333333333335)<=0.00051,ABS(B29/100-0.43333333333333335)<=0.00051),"✘ ""Más de 2"" no incluye el 2.",IF(OR(ABS(B29-9)<=0.009000000000000001,ABS(B29/100-9)<=0.009000000000000001),"✘ Eso es cuántos son. Piden la proporción: divide entre n.","✘ Revisa el cálculo.")))))

Sheet 1_Discreta_N3
A1: Variable discreta: tabla y medidas · Nivel 3 · Sin ayuda
E2: Aciertos: | F2: =SUMPRODUCT(--(LEFT($C$1:$C$27,1)="✔")) | G2: de 11
A3: Celdas azules: datos. Celdas amarillas: tu respuesta (se ponen verdes si está bien y rojas si no).
A5: Número de días de teletrabajo a la semana de 30 empleados.
A6: Datos | B6: 3 | C6: 3 | D6: 3 | E6: 0 | F6: 0 | G6: 4 | H6: 1 | I6: 0 | J6: 4 | K6: 5
B7: 0 | C7: 3 | D7: 0 | E7: 1 | F7: 3 | G7: 1 | H7: 1 | I7: 0 | J7: 3 | K7: 1
B8: 0 | C8: 2 | D8: 5 | E8: 1 | F8: 2 | G8: 5 | H8: 0 | I8: 1 | J8: 5 | K8: 0
A10: Preguntas
A11: Tamaño de la muestra (n) | C11: =IF(B11="","",IF(AND(ISNUMBER(B11),ABS(B11-Claves!$A$78)<=0.51),"✔ Bien",IF(NOT(ISNUMBER(B11)),"✘ Escribe solo el número (sin texto ni %).","✘ Revisa el cálculo.")))
A12: Media | C12: =IF(B12="","",IF(AND(ISNUMBER(B12),ABS(B12-Claves!$A$79)<=0.0051),"✔ Bien",IF(NOT(ISNUMBER(B12)),"✘ Escribe solo el número (sin texto ni %).",IF(ABS(B12-2.5)<=0.0051,"✘ Has hecho la media de los valores distintos. Cada valor cuenta tantas veces como se repite.","✘ Revisa el cálculo."))))
A13: Mediana | C13: =IF(B13="","",IF(AND(ISNUMBER(B13),ABS(B13-Claves!$A$80)<=0.0051),"✔ Bien",IF(NOT(ISNUMBER(B13)),"✘ Escribe solo el número (sin texto ni %).","✘ Revisa el cálculo.")))
A14: Moda | C14: =IF(B14="","",IF(AND(ISNUMBER(B14),ABS(B14-Claves!$A$81)<=0.51),"✔ Bien",IF(NOT(ISNUMBER(B14)),"✘ Escribe solo el número (sin texto ni %).",IF(ABS(B14-9)<=0.51,"✘ Eso es la frecuencia más alta. La moda es el VALOR que tiene esa frecuencia.","✘ Revisa el cálculo."))))
A15: Primer cuartil (con CUARTIL.INC) | C15: =IF(B15="","",IF(AND(ISNUMBER(B15),ABS(B15-Claves!$A$82)<=0.0051),"✔ Bien",IF(NOT(ISNUMBER(B15)),"✘ Escribe solo el número (sin texto ni %).","✘ Revisa el cálculo.")))
A16: Tercer cuartil (con CUARTIL.INC) | C16: =IF(B16="","",IF(AND(ISNUMBER(B16),ABS(B16-Claves!$A$83)<=0.0051),"✔ Bien",IF(NOT(ISNUMBER(B16)),"✘ Escribe solo el número (sin texto ni %).","✘ Revisa el cálculo.")))
A17: Varianza S² (la de clase) | C17: =IF(B17="","",IF(AND(ISNUMBER(B17),ABS(B17-Claves!$A$84)<=0.0030900000000000003),"✔ Bien",IF(NOT(ISNUMBER(B17)),"✘ Escribe solo el número (sin texto ni %).",IF(ABS(B17-3.1965517241379313)<=0.003196551724137931,"✘ Has calculado la cuasivarianza (VAR.S). Aquí se pide VAR.P.",IF(ABS(B17-6.7)<=0.0067,"✘ Te falta restar la media al cuadrado.","✘ Revisa el cálculo.")))))
A18: Cuasivarianza s² | C18: =IF(B18="","",IF(AND(ISNUMBER(B18),ABS(B18-Claves!$A$85)<=0.003196551724137931),"✔ Bien",IF(NOT(ISNUMBER(B18)),"✘ Escribe solo el número (sin texto ni %).",IF(ABS(B18-3.0900000000000003)<=0.0030900000000000003,"✘ Esa es la varianza (VAR.P). La cuasivarianza es VAR.S.","✘ Revisa el cálculo."))))
A19: Desviación típica S | C19: =IF(B19="","",IF(AND(ISNUMBER(B19),ABS(B19-Claves!$A$86)<=0.0017578395831246948),"✔ Bien",IF(NOT(ISNUMBER(B19)),"✘ Escribe solo el número (sin texto ni %).",IF(ABS(B19-1.7878902998053128)<=0.0017878902998053128,"✘ Has usado DESVEST.S. La desviación típica de clase es DESVEST.P.",IF(ABS(B19-3.0900000000000003)<=0.0030900000000000003,"✘ Eso es la varianza. La desviación típica es su raíz.","✘ Revisa el cálculo.")))))
A20: Coeficiente de variación (en decimal) | C20: =IF(B20="","",IF(AND(ISNUMBER(B20),OR(ABS(B20-Claves!$A$87)<=0.0009251787279603657,ABS(B20/100-Claves!$A$87)<=0.0009251787279603657)),"✔ Bien",IF(NOT(ISNUMBER(B20)),"✘ Escribe solo el número (sin texto ni %).",IF(OR(ABS(B20-0.9409948946343752)<=0.0009409948946343753,ABS(B20/100-0.9409948946343752)<=0.0009409948946343753),"✘ Usa DESVEST.P en el CV, no DESVEST.S.",IF(OR(ABS(B20-1.0808722355782912)<=0.0010808722355782911,ABS(B20/100-1.0808722355782912)<=0.0010808722355782911),"✘ Está al revés: CV = desviación típica ÷ media.","✘ Revisa el cálculo.")))))
A21: Proporción de empleados con más de 2 (en decimal o %) | C21: =IF(B21="","",IF(AND(ISNUMBER(B21),OR(ABS(B21-Claves!$A$88)<=0.00051,ABS(B21/100-Claves!$A$88)<=0.00051)),"✔ Bien",IF(NOT(ISNUMBER(B21)),"✘ Escribe solo el número (sin texto ni %).",IF(OR(ABS(B21-0.4666666666666667)<=0.00051,ABS(B21/100-0.4666666666666667)<=0.00051),"✘ ""Más de 2"" no incluye el 2.",IF(OR(ABS(B21-12)<=0.012,ABS(B21/100-12)<=0.012),"✘ Eso es cuántos son. Piden la proporción: divide entre n.","✘ Revisa el cálculo.")))))

Sheet 2_Intervalos_N1
A1: Datos en intervalos (amplitudes distintas) · Nivel 1 · Con guía
E2: Aciertos: | F2: =SUMPRODUCT(--(LEFT($C$1:$C$30,1)="✔")) | G2: de 8
A3: Celdas azules: datos. Celdas amarillas: tu respuesta (se ponen verdes si está bien y rojas si no).
A5: Salario mensual (€) de los empleados de una empresa.
A6: Paso 1 · Tabla de trabajo
A7: 💡 Marca = punto medio. Amplitud = extremo superior − inferior. Densidad = nᵢ ÷ amplitud (las amplitudes NO son iguales).
A8: Intervalo | B8: nᵢ | C8: Marca xᵢ | D8: Amplitud aᵢ | E8: Densidad dᵢ | F8: xᵢ·nᵢ | G8: xᵢ²·nᵢ | H8: Nᵢ
A9: Pista → | C9: ej. =(Linf+Lsup)/2 | D9: ej. =Lsup−Linf | E9: ej. =nᵢ/aᵢ | F9: ej. =xᵢ*nᵢ | G9: ej. =xᵢ^2*nᵢ | H9: ej. =Nᵢ₋₁+nᵢ
A10: [800, 1000] | B10: 8
A11: (1000, 1200] | B11: 22
A12: (1200, 1500] | B12: 33
A13: (1500, 2000] | B13: 27
A14: (2000, 3000] | B14: 10
A16: Paso 2 · Medidas
A17: n (total) | C17: =IF(B17="","",IF(AND(ISNUMBER(B17),ABS(B17-Claves!$A$119)<=0.51),"✔ Bien",IF(NOT(ISNUMBER(B17)),"✘ Escribe solo el número (sin texto ni %).","✘ Revisa el cálculo.")))
A18: Media | C18: =IF(B18="","",IF(AND(ISNUMBER(B18),ABS(B18-Claves!$A$120)<=1.482),"✔ Bien",IF(NOT(ISNUMBER(B18)),"✘ Escribe solo el número (sin texto ni %).",IF(ABS(B18-1520)<=1.52,"✘ Has promediado las marcas sin multiplicar por las frecuencias.","✘ Revisa el cálculo."))))
A19: Varianza S² | C19: =IF(B19="","",IF(AND(ISNUMBER(B19),ABS(B19-Claves!$A$121)<=187.976),"✔ Bien",IF(NOT(ISNUMBER(B19)),"✘ Escribe solo el número (sin texto ni %).",IF(ABS(B19-2384300)<=2384.3,"✘ Te falta restar la media al cuadrado.",IF(ABS(B19-189874.74747474748)<=189.8747474747475,"✘ Esa es la cuasivarianza (divide entre n−1). Aquí se pide la varianza.","✘ Revisa el cálculo.")))))
A20: Desviación típica S | C20: =IF(B20="","",IF(AND(ISNUMBER(B20),ABS(B20-Claves!$A$122)<=0.43356199095400416),"✔ Bien",IF(NOT(ISNUMBER(B20)),"✘ Escribe solo el número (sin texto ni %).","✘ Revisa el cálculo.")))
A21: Coeficiente de variación (decimal) | C21: =IF(B21="","",IF(AND(ISNUMBER(B21),OR(ABS(B21-Claves!$A$123)<=0.00051,ABS(B21/100-Claves!$A$123)<=0.00051)),"✔ Bien",IF(NOT(ISNUMBER(B21)),"✘ Escribe solo el número (sin texto ni %).","✘ Revisa el cálculo.")))
A22: Moda (fórmula de intervalos) | C22: =IF(B22="","",IF(AND(ISNUMBER(B22),ABS(B22-Claves!$A$124)<=1.2),"✔ Bien",IF(NOT(ISNUMBER(B22)),"✘ Escribe solo el número (sin texto ni %).",IF(ABS(B22-1394.1176470588234)<=1.3941176470588235,"✘ Has usado las frecuencias. Con amplitudes distintas, el intervalo modal se elige por la DENSIDAD.","✘ Revisa el cálculo."))))
A23: Mediana | C23: =IF(B23="","",IF(AND(ISNUMBER(B23),ABS(B23-Claves!$A$125)<=1.3818181818181818),"✔ Bien",IF(NOT(ISNUMBER(B23)),"✘ Escribe solo el número (sin texto ni %).",IF(ABS(B23-1350)<=1.35,"✘ Eso es la marca del intervalo. Aplica la fórmula: Linf + (n/2 − Nᵢ₋₁)/nᵢ · aᵢ.","✘ Revisa el cálculo."))))
A24: ¿A partir de qué valor se está en el 20 % con valores más altos? | C24: =IF(B24="","",IF(AND(ISNUMBER(B24),ABS(B24-Claves!$A$126)<=1.8148148148148149),"✔ Bien",IF(NOT(ISNUMBER(B24)),"✘ Escribe solo el número (sin texto ni %).",IF(ABS(B24-1109.090909090909)<=1.1090909090909091,"✘ Ese es el percentil 20. ""El 20 % de arriba"" empieza en el percentil 80.","✘ Revisa el cálculo."))))

Sheet 2_Intervalos_N2
A1: Datos en intervalos (amplitudes distintas) · Nivel 2 · Con cabeceras
E2: Aciertos: | F2: =SUMPRODUCT(--(LEFT($C$1:$C$28,1)="✔")) | G2: de 8
A3: Celdas azules: datos. Celdas amarillas: tu respuesta (se ponen verdes si está bien y rojas si no).
A5: Superficie (m²) de viviendas de alquiler.
A6: Paso 1 · Tabla de trabajo
A7: Intervalo | B7: nᵢ | C7: Marca xᵢ | D7: Amplitud aᵢ | E7: Densidad dᵢ | F7: xᵢ·nᵢ | G7: xᵢ²·nᵢ | H7: Nᵢ
A8: [20, 30] | B8: 7
A9: (30, 40] | B9: 14
A10: (40, 60] | B10: 39
A11: (60, 80] | B11: 25
A12: (80, 120] | B12: 16
A14: Paso 2 · Medidas
A15: n (total) | C15: =IF(B15="","",IF(AND(ISNUMBER(B15),ABS(B15-Claves!$A$157)<=0.51),"✔ Bien",IF(NOT(ISNUMBER(B15)),"✘ Escribe solo el número (sin texto ni %).","✘ Revisa el cálculo.")))
A16: Media | C16: =IF(B16="","",IF(AND(ISNUMBER(B16),ABS(B16-Claves!$A$158)<=0.05905940594059406),"✔ Bien",IF(NOT(ISNUMBER(B16)),"✘ Escribe solo el número (sin texto ni %).",IF(ABS(B16-56)<=0.056,"✘ Has promediado las marcas sin multiplicar por las frecuencias.","✘ Revisa el cálculo."))))
A17: Varianza S² | C17: =IF(B17="","",IF(AND(ISNUMBER(B17),ABS(B17-Claves!$A$159)<=0.4874816194490736),"✔ Bien",IF(NOT(ISNUMBER(B17)),"✘ Escribe solo el número (sin texto ni %).",IF(ABS(B17-3975.4950495049507)<=3.975495049504951,"✘ Te falta restar la media al cuadrado.",IF(ABS(B17-492.35643564356434)<=0.49235643564356435,"✘ Esa es la cuasivarianza (divide entre n−1). Aquí se pide la varianza.","✘ Revisa el cálculo.")))))
A18: Desviación típica S | C18: =IF(B18="","",IF(AND(ISNUMBER(B18),ABS(B18-Claves!$A$160)<=0.022078985924382344),"✔ Bien",IF(NOT(ISNUMBER(B18)),"✘ Escribe solo el número (sin texto ni %).","✘ Revisa el cálculo.")))
A19: Coeficiente de variación (decimal) | C19: =IF(B19="","",IF(AND(ISNUMBER(B19),OR(ABS(B19-Claves!$A$161)<=0.00051,ABS(B19/100-Claves!$A$161)<=0.00051)),"✔ Bien",IF(NOT(ISNUMBER(B19)),"✘ Escribe solo el número (sin texto ni %).","✘ Revisa el cálculo.")))
A20: Moda (fórmula de intervalos) | C20: =IF(B20="","",IF(AND(ISNUMBER(B20),ABS(B20-Claves!$A$162)<=0.048799999999999996),"✔ Bien",IF(NOT(ISNUMBER(B20)),"✘ Escribe solo el número (sin texto ni %).",IF(ABS(B20-52.82051282051282)<=0.05282051282051282,"✘ Has usado las frecuencias. Con amplitudes distintas, el intervalo modal se elige por la DENSIDAD.","✘ Revisa el cálculo."))))
A21: Mediana | C21: =IF(B21="","",IF(AND(ISNUMBER(B21),ABS(B21-Claves!$A$163)<=0.05512820512820513),"✔ Bien",IF(NOT(ISNUMBER(B21)),"✘ Escribe solo el número (sin texto ni %).",IF(ABS(B21-50)<=0.05,"✘ Eso es la marca del intervalo. Aplica la fórmula: Linf + (n/2 − Nᵢ₋₁)/nᵢ · aᵢ.","✘ Revisa el cálculo."))))
A22: ¿A partir de qué valor se está en el 20 % con valores más altos? | C22: =IF(B22="","",IF(AND(ISNUMBER(B22),ABS(B22-Claves!$A$164)<=0.07664000000000001),"✔ Bien",IF(NOT(ISNUMBER(B22)),"✘ Escribe solo el número (sin texto ni %).",IF(ABS(B22-39.42857142857143)<=0.03942857142857143,"✘ Ese es el percentil 20. ""El 20 % de arriba"" empieza en el percentil 80.","✘ Revisa el cálculo."))))

Sheet 2_Intervalos_N3
A1: Datos en intervalos (amplitudes distintas) · Nivel 3 · Sin ayuda
E2: Aciertos: | F2: =SUMPRODUCT(--(LEFT($C$1:$C$27,1)="✔")) | G2: de 8
A3: Celdas azules: datos. Celdas amarillas: tu respuesta (se ponen verdes si está bien y rojas si no).
A5: Antigüedad (años) del personal de un hospital.
A6: Intervalo | B6: nᵢ
A7: [0, 5] | B7: 10
A8: (5, 10] | B8: 19
A9: (10, 20] | B9: 31
A10: (20, 30] | B10: 23
A11: (30, 50] | B11: 6
A13: Preguntas
A14: n (total) | C14: =IF(B14="","",IF(AND(ISNUMBER(B14),ABS(B14-Claves!$A$165)<=0.51),"✔ Bien",IF(NOT(ISNUMBER(B14)),"✘ Escribe solo el número (sin texto ni %).","✘ Revisa el cálculo.")))
A15: Media | C15: =IF(B15="","",IF(AND(ISNUMBER(B15),ABS(B15-Claves!$A$166)<=0.016264044943820225),"✔ Bien",IF(NOT(ISNUMBER(B15)),"✘ Escribe solo el número (sin texto ni %).",IF(ABS(B15-18)<=0.018000000000000002,"✘ Has promediado las marcas sin multiplicar por las frecuencias.","✘ Revisa el cálculo."))))
A16: Varianza S² | C16: =IF(B16="","",IF(AND(ISNUMBER(B16),ABS(B16-Claves!$A$167)<=0.09594432521146319),"✔ Bien",IF(NOT(ISNUMBER(B16)),"✘ Escribe solo el número (sin texto ni %).",IF(ABS(B16-360.4634831460674)<=0.3604634831460674,"✘ Te falta restar la media al cuadrado.",IF(ABS(B16-97.03460163432074)<=0.09703460163432073,"✘ Esa es la cuasivarianza (divide entre n−1). Aquí se pide la varianza.","✘ Revisa el cálculo.")))))
A17: Desviación típica S | C17: =IF(B17="","",IF(AND(ISNUMBER(B17),ABS(B17-Claves!$A$168)<=0.009795117416930907),"✔ Bien",IF(NOT(ISNUMBER(B17)),"✘ Escribe solo el número (sin texto ni %).","✘ Revisa el cálculo.")))
A18: Coeficiente de variación (decimal) | C18: =IF(B18="","",IF(AND(ISNUMBER(B18),OR(ABS(B18-Claves!$A$169)<=0.0006022559240807259,ABS(B18/100-Claves!$A$169)<=0.0006022559240807259)),"✔ Bien",IF(NOT(ISNUMBER(B18)),"✘ Escribe solo el número (sin texto ni %).","✘ Revisa el cálculo.")))
A19: Moda (fórmula de intervalos) | C19: =IF(B19="","",IF(AND(ISNUMBER(B19),ABS(B19-Claves!$A$170)<=0.008600000000000002),"✔ Bien",IF(NOT(ISNUMBER(B19)),"✘ Escribe solo el número (sin texto ni %).",IF(ABS(B19-16)<=0.016,"✘ Has usado las frecuencias. Con amplitudes distintas, el intervalo modal se elige por la DENSIDAD.","✘ Revisa el cálculo."))))
A20: Mediana | C20: =IF(B20="","",IF(AND(ISNUMBER(B20),ABS(B20-Claves!$A$171)<=0.015),"✔ Bien",IF(NOT(ISNUMBER(B20)),"✘ Escribe solo el número (sin texto ni %).","✘ Revisa el cálculo.")))
A21: ¿A partir de qué valor se está en el 20 % con valores más altos? | C21: =IF(B21="","",IF(AND(ISNUMBER(B21),ABS(B21-Claves!$A$172)<=0.024869565217391306),"✔ Bien",IF(NOT(ISNUMBER(B21)),"✘ Escribe solo el número (sin texto ni %).",IF(ABS(B21-7.052631578947368)<=0.0070526315789473685,"✘ Ese es el percentil 20. ""El 20 % de arriba"" empieza en el percentil 80.","✘ Revisa el cálculo."))))

Sheet 3_Grupos_N1
A1: Varianza dentro y entre grupos + cambios de escala · Nivel 1 · Con guía
E2: Aciertos: | F2: =SUMPRODUCT(--(LEFT($C$1:$C$36,1)="✔")) | G2: de 9
A3: Celdas azules: datos. Celdas amarillas: tu respuesta (se ponen verdes si está bien y rojas si no).
A5: Salario medio por grupo (€). Te dan el tamaño, la media y la DESVIACIÓN TÍPICA de cada grupo.
A6: Grupo | B6: Tamaño T | C6: Media | D6: Desv. típica
A7: Administración | B7: 40 | C7: 1650 | D7: 210
A8: Producción | B8: 90 | C8: 1480 | D8: 160
A9: Ventas | B9: 30 | C9: 1920 | D9: 380
A11: Paso 1 · Tabla de trabajo
A12: 💡 Varianza = desviación típica al cuadrado. Para la "entre" necesitas antes la media global (pregunta 1).
A13: Grupo | B13: Varianza | C13: Varianza·T | D13: CV | E13: (media−global)²·T
A14: Pista → | B14: ej. =Desv^2 | C14: ej. =Varianza*T | D14: ej. =Desv/Media | E14: ej. =(Media−global)^2*T
A15: Administración
A16: Producción
A17: Ventas
A19: Preguntas
A20: ¿Qué grupo es más homogéneo? (escribe el nombre) | C20: =IF(B20="","",IF(OR(UPPER(TRIM(B20))="PRODUCCIÓN"),"✔ Bien","✘ Revisa la respuesta."))
A21: Media global | C21: =IF(B21="","",IF(AND(ISNUMBER(B21),ABS(B21-Claves!$A$186)<=1.605),"✔ Bien",IF(NOT(ISNUMBER(B21)),"✘ Escribe solo el número (sin texto ni %).",IF(ABS(B21-1683.3333333333333)<=1.6833333333333333,"✘ Has hecho la media de las medias sin ponderar por el tamaño de cada grupo.","✘ Revisa el cálculo."))))
A22: Varianza dentro de los grupos | C22: =IF(B22="","",IF(AND(ISNUMBER(B22),ABS(B22-Claves!$A$187)<=52.5),"✔ Bien",IF(NOT(ISNUMBER(B22)),"✘ Escribe solo el número (sin texto ni %).",IF(ABS(B22-213.75)<=0.21375,"✘ Has usado las desviaciones típicas. Hay que elevarlas al cuadrado (varianzas).","✘ Revisa el cálculo."))))
A23: Varianza entre los grupos | C23: =IF(B23="","",IF(AND(ISNUMBER(B23),ABS(B23-Claves!$A$188)<=27.900000000000002),"✔ Bien",IF(NOT(ISNUMBER(B23)),"✘ Escribe solo el número (sin texto ni %).","✘ Revisa el cálculo.")))
A24: Varianza total | C24: =IF(B24="","",IF(AND(ISNUMBER(B24),ABS(B24-Claves!$A$189)<=80.4),"✔ Bien",IF(NOT(ISNUMBER(B24)),"✘ Escribe solo el número (sin texto ni %).","✘ Revisa el cálculo.")))
A25: Desviación típica total | C25: =IF(B25="","",IF(AND(ISNUMBER(B25),ABS(B25-Claves!$A$190)<=0.28354893757515653),"✔ Bien",IF(NOT(ISNUMBER(B25)),"✘ Escribe solo el número (sin texto ni %).",IF(ABS(B25-80400)<=80.4,"✘ Eso es la varianza. Haz la raíz cuadrada.","✘ Revisa el cálculo."))))
A26: % de la variabilidad debido a las diferencias entre grupos | C26: =IF(B26="","",IF(AND(ISNUMBER(B26),OR(ABS(B26-Claves!$A$191)<=0.00051,ABS(B26/100-Claves!$A$191)<=0.00051)),"✔ Bien",IF(NOT(ISNUMBER(B26)),"✘ Escribe solo el número (sin texto ni %).",IF(OR(ABS(B26-0.6529850746268657)<=0.0006529850746268657,ABS(B26/100-0.6529850746268657)<=0.0006529850746268657),"✘ Ese es el % de dentro de los grupos.","✘ Revisa el cálculo."))))
A28: Si todos los salarios suben un 3 %:
A29: Nueva media global | C29: =IF(B29="","",IF(AND(ISNUMBER(B29),ABS(B29-Claves!$A$192)<=1.6531500000000001),"✔ Bien",IF(NOT(ISNUMBER(B29)),"✘ Escribe solo el número (sin texto ni %).","✘ Revisa el cálculo.")))
A30: Nueva varianza total | C30: =IF(B30="","",IF(AND(ISNUMBER(B30),ABS(B30-Claves!$A$193)<=85.29636),"✔ Bien",IF(NOT(ISNUMBER(B30)),"✘ Escribe solo el número (sin texto ni %).",IF(ABS(B30-82812)<=82.812,"✘ La varianza se multiplica por a² (no por a).","✘ Revisa el cálculo."))))

Sheet 3_Grupos_N2
A1: Varianza dentro y entre grupos + cambios de escala · Nivel 2 · Con cabeceras
E2: Aciertos: | F2: =SUMPRODUCT(--(LEFT($C$1:$C$32,1)="✔")) | G2: de 9
A3: Celdas azules: datos. Celdas amarillas: tu respuesta (se ponen verdes si está bien y rojas si no).
A5: Salario medio por grupo (€). Te dan el tamaño, la media y la DESVIACIÓN TÍPICA de cada grupo.
A6: Grupo | B6: Tamaño T | C6: Media | D6: Desv. típica
A7: Hombres | B7: 120 | C7: 2350 | D7: 420
A8: Mujeres | B8: 80 | C8: 2080 | D8: 300
A10: Paso 1 · Tabla de trabajo
A11: Grupo | B11: Varianza | C11: Varianza·T | D11: CV | E11: (media−global)²·T
A12: Hombres
A13: Mujeres
A15: Preguntas
A16: ¿Qué grupo es más homogéneo? (escribe el nombre) | C16: =IF(B16="","",IF(OR(UPPER(TRIM(B16))="MUJERES"),"✔ Bien","✘ Revisa la respuesta."))
A17: Media global | C17: =IF(B17="","",IF(AND(ISNUMBER(B17),ABS(B17-Claves!$A$203)<=2.242),"✔ Bien",IF(NOT(ISNUMBER(B17)),"✘ Escribe solo el número (sin texto ni %).",IF(ABS(B17-2215)<=2.215,"✘ Has hecho la media de las medias sin ponderar por el tamaño de cada grupo.","✘ Revisa el cálculo."))))
A18: Varianza dentro de los grupos | C18: =IF(B18="","",IF(AND(ISNUMBER(B18),ABS(B18-Claves!$A$204)<=141.84),"✔ Bien",IF(NOT(ISNUMBER(B18)),"✘ Escribe solo el número (sin texto ni %).",IF(ABS(B18-372)<=0.372,"✘ Has usado las desviaciones típicas. Hay que elevarlas al cuadrado (varianzas).","✘ Revisa el cálculo."))))
A19: Varianza entre los grupos | C19: =IF(B19="","",IF(AND(ISNUMBER(B19),ABS(B19-Claves!$A$205)<=17.496),"✔ Bien",IF(NOT(ISNUMBER(B19)),"✘ Escribe solo el número (sin texto ni %).","✘ Revisa el cálculo.")))
A20: Varianza total | C20: =IF(B20="","",IF(AND(ISNUMBER(B20),ABS(B20-Claves!$A$206)<=159.336),"✔ Bien",IF(NOT(ISNUMBER(B20)),"✘ Escribe solo el número (sin texto ni %).","✘ Revisa el cálculo.")))
A21: Desviación típica total | C21: =IF(B21="","",IF(AND(ISNUMBER(B21),ABS(B21-Claves!$A$207)<=0.39916913708351753),"✔ Bien",IF(NOT(ISNUMBER(B21)),"✘ Escribe solo el número (sin texto ni %).",IF(ABS(B21-159336)<=159.336,"✘ Eso es la varianza. Haz la raíz cuadrada.","✘ Revisa el cálculo."))))
A22: % de la variabilidad debido a las diferencias entre grupos | C22: =IF(B22="","",IF(AND(ISNUMBER(B22),OR(ABS(B22-Claves!$A$208)<=0.00051,ABS(B22/100-Claves!$A$208)<=0.00051)),"✔ Bien",IF(NOT(ISNUMBER(B22)),"✘ Escribe solo el número (sin texto ni %).",IF(OR(ABS(B22-0.8901943063714415)<=0.0008901943063714415,ABS(B22/100-0.8901943063714415)<=0.0008901943063714415),"✘ Ese es el % de dentro de los grupos.","✘ Revisa el cálculo."))))
A24: Si todos los salarios suben un 2 % y además 40 €:
A25: Nueva media global | C25: =IF(B25="","",IF(AND(ISNUMBER(B25),ABS(B25-Claves!$A$209)<=2.3268400000000002),"✔ Bien",IF(NOT(ISNUMBER(B25)),"✘ Escribe solo el número (sin texto ni %).","✘ Revisa el cálculo.")))
A26: Nueva varianza total | C26: =IF(B26="","",IF(AND(ISNUMBER(B26),ABS(B26-Claves!$A$210)<=165.7731744),"✔ Bien",IF(NOT(ISNUMBER(B26)),"✘ Escribe solo el número (sin texto ni %).",IF(ABS(B26-162522.72)<=162.52272,"✘ La varianza se multiplica por a² (no por a).","✘ Revisa el cálculo."))))

Sheet 3_Grupos_N3
A1: Varianza dentro y entre grupos + cambios de escala · Nivel 3 · Sin ayuda
E2: Aciertos: | F2: =SUMPRODUCT(--(LEFT($C$1:$C$28,1)="✔")) | G2: de 9
A3: Celdas azules: datos. Celdas amarillas: tu respuesta (se ponen verdes si está bien y rojas si no).
A5: Salario medio por grupo (miles de €). Te dan el tamaño, la media y la DESVIACIÓN TÍPICA de cada grupo.
A6: Grupo | B6: Tamaño T | C6: Media | D6: Desv. típica
A7: Centro A | B7: 25 | C7: 24.5 | D7: 4.1
A8: Centro B | B8: 60 | C8: 21 | D8: 3.2
A9: Centro C | B9: 35 | C9: 27.5 | D9: 6
A11: Preguntas
A12: ¿Qué grupo es más homogéneo? (escribe el nombre) | C12: =IF(B12="","",IF(OR(UPPER(TRIM(B12))="CENTRO B"),"✔ Bien","✘ Revisa la respuesta."))
A13: Media global | C13: =IF(B13="","",IF(AND(ISNUMBER(B13),ABS(B13-Claves!$A$212)<=0.023625),"✔ Bien",IF(NOT(ISNUMBER(B13)),"✘ Escribe solo el número (sin texto ni %).",IF(ABS(B13-24.333333333333332)<=0.024333333333333332,"✘ Has hecho la media de las medias sin ponderar por el tamaño de cada grupo.","✘ Revisa el cálculo."))))
A14: Varianza dentro de los grupos | C14: =IF(B14="","",IF(AND(ISNUMBER(B14),ABS(B14-Claves!$A$213)<=0.051000000000000004),"✔ Bien",IF(NOT(ISNUMBER(B14)),"✘ Escribe solo el número (sin texto ni %).",IF(ABS(B14-4.204166666666667)<=0.051000000000000004,"✘ Has usado las desviaciones típicas. Hay que elevarlas al cuadrado (varianzas).","✘ Revisa el cálculo."))))
A15: Varianza entre los grupos | C15: =IF(B15="","",IF(AND(ISNUMBER(B15),ABS(B15-Claves!$A$214)<=0.051000000000000004),"✔ Bien",IF(NOT(ISNUMBER(B15)),"✘ Escribe solo el número (sin texto ni %).","✘ Revisa el cálculo.")))
A16: Varianza total | C16: =IF(B16="","",IF(AND(ISNUMBER(B16),ABS(B16-Claves!$A$215)<=0.051000000000000004),"✔ Bien",IF(NOT(ISNUMBER(B16)),"✘ Escribe solo el número (sin texto ni %).","✘ Revisa el cálculo.")))
A17: Desviación típica total | C17: =IF(B17="","",IF(AND(ISNUMBER(B17),ABS(B17-Claves!$A$216)<=0.005206386302737565),"✔ Bien",IF(NOT(ISNUMBER(B17)),"✘ Escribe solo el número (sin texto ni %).",IF(ABS(B17-27.106458333333332)<=0.027106458333333333,"✘ Eso es la varianza. Haz la raíz cuadrada.","✘ Revisa el cálculo."))))
A18: % de la variabilidad debido a las diferencias entre grupos | C18: =IF(B18="","",IF(AND(ISNUMBER(B18),OR(ABS(B18-Claves!$A$217)<=0.00051,ABS(B18/100-Claves!$A$217)<=0.00051)),"✔ Bien",IF(NOT(ISNUMBER(B18)),"✘ Escribe solo el número (sin texto ni %).",IF(OR(ABS(B18-0.7054438133593623)<=0.0007054438133593623,ABS(B18/100-0.7054438133593623)<=0.0007054438133593623),"✘ Ese es el % de dentro de los grupos.","✘ Revisa el cálculo."))))
A20: Si todos los salarios aumentan 1,5 (miles de €) a todos:
A21: Nueva media global | C21: =IF(B21="","",IF(AND(ISNUMBER(B21),ABS(B21-Claves!$A$218)<=0.025125),"✔ Bien",IF(NOT(ISNUMBER(B21)),"✘ Escribe solo el número (sin texto ni %).","✘ Revisa el cálculo.")))
A22: Nueva varianza total | C22: =IF(B22="","",IF(AND(ISNUMBER(B22),ABS(B22-Claves!$A$219)<=0.051000000000000004),"✔ Bien",IF(NOT(ISNUMBER(B22)),"✘ Escribe solo el número (sin texto ni %).",IF(ABS(B22-28.606458333333332)<=0.051000000000000004,"✘ Sumar una cantidad fija NO cambia la varianza.",IF(ABS(B22-28.606458333333332)<=0.051000000000000004,"✘ Sumar una cantidad fija NO cambia la varianza.","✘ Revisa el cálculo.")))))

Sheet 4_Contingencia_N1
A1: Tabla de doble entrada e independencia · Nivel 1 · Con guía
E2: Aciertos: | F2: =SUMPRODUCT(--(LEFT($C$1:$C$39,1)="✔")) | G2: de 7
A3: Celdas azules: datos. Celdas amarillas: tu respuesta (se ponen verdes si está bien y rojas si no).
A5: 140 trabajadores según turno (filas) y satisfacción (columnas).
A6: Turno \ Satisfacción | B6: Alta | C6: Media | D6: Baja
A7: Mañana | B7: 22 | C7: 18 | D7: 8
A8: Tarde | B8: 14 | C8: 20 | D8: 16
A9: Noche | B9: 5 | C9: 11 | D9: 26
A11: Paso 1 · Totales y frecuencias relativas fᵢⱼ = nᵢⱼ / n
A12: 💡 Total de fila = suma de la fila. fᵢⱼ = cada casilla ÷ n. Independencia: compara fᵢⱼ con fᵢ.·f.ⱼ en TODAS las casillas.
B13: Total fila | C13: f · Alta | D13: f · Media | E13: f · Baja
A14: Pista → | B14: ej. =SUMA(fila) | C14: ej. =nᵢⱼ/n | D14: ej. =nᵢⱼ/n | E14: ej. =nᵢⱼ/n
A15: Mañana
A16: Tarde
A17: Noche
A19: Ahora lo que habría si fueran independientes, fᵢ. × f.ⱼ:
B20: fᵢ.·f.ⱼ · Alta | C20: fᵢ.·f.ⱼ · Media | D20: fᵢ.·f.ⱼ · Baja
A21: Pista → | B21: ej. =(total fila/n)*(total col/n) | C21: ej. =(total fila/n)*(total col/n) | D21: ej. =(total fila/n)*(total col/n)
A22: Mañana
A23: Tarde
A24: Noche
A26: Preguntas
A27: n (total) | C27: =IF(B27="","",IF(AND(ISNUMBER(B27),ABS(B27-Claves!$A$241)<=0.51),"✔ Bien",IF(NOT(ISNUMBER(B27)),"✘ Escribe solo el número (sin texto ni %).","✘ Revisa el cálculo.")))
A28: Distribución marginal: total de "Media" | C28: =IF(B28="","",IF(AND(ISNUMBER(B28),ABS(B28-Claves!$A$242)<=0.51),"✔ Bien",IF(NOT(ISNUMBER(B28)),"✘ Escribe solo el número (sin texto ni %).","✘ Revisa el cálculo.")))
A29: f₁₁ (proporción de Mañana y Alta, en decimal) | C29: =IF(B29="","",IF(AND(ISNUMBER(B29),OR(ABS(B29-Claves!$A$243)<=0.00051,ABS(B29/100-Claves!$A$243)<=0.00051)),"✔ Bien",IF(NOT(ISNUMBER(B29)),"✘ Escribe solo el número (sin texto ni %).","✘ Revisa el cálculo.")))
A30: f₁. × f.₁ (lo que habría si fueran independientes) | C30: =IF(B30="","",IF(AND(ISNUMBER(B30),OR(ABS(B30-Claves!$A$244)<=0.00051,ABS(B30/100-Claves!$A$244)<=0.00051)),"✔ Bien",IF(NOT(ISNUMBER(B30)),"✘ Escribe solo el número (sin texto ni %).","✘ Revisa el cálculo.")))
A31: De los de Noche, ¿qué proporción es "Baja"? (Satisfacción | Turno = Noche) | C31: =IF(B31="","",IF(AND(ISNUMBER(B31),OR(ABS(B31-Claves!$A$245)<=0.0006190476190476191,ABS(B31/100-Claves!$A$245)<=0.0006190476190476191)),"✔ Bien",IF(NOT(ISNUMBER(B31)),"✘ Escribe solo el número (sin texto ni %).",IF(OR(ABS(B31-0.18571428571428572)<=0.00051,ABS(B31/100-0.18571428571428572)<=0.00051),"✘ En una condicionada se divide entre el total de la FILA, no entre n.",IF(OR(ABS(B31-0.52)<=0.0005200000000000001,ABS(B31/100-0.52)<=0.0005200000000000001),"✘ Eso es Turno | Satisfacción: has dividido entre el total de la columna.","✘ Revisa el cálculo.")))))
A32: De los "Alta", ¿qué proporción es de Tarde? (Turno | Satisfacción = Alta) | C32: =IF(B32="","",IF(AND(ISNUMBER(B32),OR(ABS(B32-Claves!$A$246)<=0.00051,ABS(B32/100-Claves!$A$246)<=0.00051)),"✔ Bien",IF(NOT(ISNUMBER(B32)),"✘ Escribe solo el número (sin texto ni %).",IF(OR(ABS(B32-0.28)<=0.00051,ABS(B32/100-0.28)<=0.00051),"✘ Eso es la condicionada por fila. Aquí te restringes a la COLUMNA.",IF(OR(ABS(B32-0.1)<=0.00051,ABS(B32/100-0.1)<=0.00051),"✘ Divide entre el total de la columna, no entre n.","✘ Revisa el cálculo.")))))
A33: ¿Son independientes? (Sí / No) | C33: =IF(B33="","",IF(OR(UPPER(TRIM(B33))="NO"),"✔ Bien",IF(UPPER(TRIM(B33))="SI","✘ Compara fᵢⱼ con fᵢ.×f.ⱼ en todas las casillas (o los % de cada fila).",IF(UPPER(TRIM(B33))="SÍ","✘ Compara fᵢⱼ con fᵢ.×f.ⱼ en todas las casillas (o los % de cada fila).","✘ Revisa la respuesta."))))

Sheet 4_Contingencia_N2
A1: Tabla de doble entrada e independencia · Nivel 2 · Con cabeceras
E2: Aciertos: | F2: =SUMPRODUCT(--(LEFT($C$1:$C$36,1)="✔")) | G2: de 7
A3: Celdas azules: datos. Celdas amarillas: tu respuesta (se ponen verdes si está bien y rojas si no).
A5: 150 trabajadores según departamento (filas) y contrato (columnas).
A6: Departamento \ Contrato | B6: Indefinido | C6: Temporal | D6: Parcial
A7: RRHH | B7: 18 | C7: 6 | D7: 6
A8: Ventas | B8: 30 | C8: 10 | D8: 10
A9: Producción | B9: 42 | C9: 14 | D9: 14
A11: Paso 1 · Totales y frecuencias relativas fᵢⱼ = nᵢⱼ / n
B12: Total fila | C12: f · Indefinido | D12: f · Temporal | E12: f · Parcial
A13: RRHH
A14: Ventas
A15: Producción
A17: Ahora lo que habría si fueran independientes, fᵢ. × f.ⱼ:
B18: fᵢ.·f.ⱼ · Indefinido | C18: fᵢ.·f.ⱼ · Temporal | D18: fᵢ.·f.ⱼ · Parcial
A19: RRHH
A20: Ventas
A21: Producción
A23: Preguntas
A24: n (total) | C24: =IF(B24="","",IF(AND(ISNUMBER(B24),ABS(B24-Claves!$A$269)<=0.51),"✔ Bien",IF(NOT(ISNUMBER(B24)),"✘ Escribe solo el número (sin texto ni %).","✘ Revisa el cálculo.")))
A25: Distribución marginal: total de "Temporal" | C25: =IF(B25="","",IF(AND(ISNUMBER(B25),ABS(B25-Claves!$A$270)<=0.51),"✔ Bien",IF(NOT(ISNUMBER(B25)),"✘ Escribe solo el número (sin texto ni %).","✘ Revisa el cálculo.")))
A26: f₁₁ (proporción de RRHH y Indefinido, en decimal) | C26: =IF(B26="","",IF(AND(ISNUMBER(B26),OR(ABS(B26-Claves!$A$271)<=0.00051,ABS(B26/100-Claves!$A$271)<=0.00051)),"✔ Bien",IF(NOT(ISNUMBER(B26)),"✘ Escribe solo el número (sin texto ni %).","✘ Revisa el cálculo.")))
A27: f₁. × f.₁ (lo que habría si fueran independientes) | C27: =IF(B27="","",IF(AND(ISNUMBER(B27),OR(ABS(B27-Claves!$A$272)<=0.00051,ABS(B27/100-Claves!$A$272)<=0.00051)),"✔ Bien",IF(NOT(ISNUMBER(B27)),"✘ Escribe solo el número (sin texto ni %).","✘ Revisa el cálculo.")))
A28: De los de Producción, ¿qué proporción es "Parcial"? (Contrato | Departamento = Producción) | C28: =IF(B28="","",IF(AND(ISNUMBER(B28),OR(ABS(B28-Claves!$A$273)<=0.00051,ABS(B28/100-Claves!$A$273)<=0.00051)),"✔ Bien",IF(NOT(ISNUMBER(B28)),"✘ Escribe solo el número (sin texto ni %).",IF(OR(ABS(B28-0.09333333333333334)<=0.00051,ABS(B28/100-0.09333333333333334)<=0.00051),"✘ En una condicionada se divide entre el total de la FILA, no entre n.",IF(OR(ABS(B28-0.4666666666666667)<=0.00051,ABS(B28/100-0.4666666666666667)<=0.00051),"✘ Eso es Departamento | Contrato: has dividido entre el total de la columna.","✘ Revisa el cálculo.")))))
A29: De los "Indefinido", ¿qué proporción es de Ventas? (Departamento | Contrato = Indefinido) | C29: =IF(B29="","",IF(AND(ISNUMBER(B29),OR(ABS(B29-Claves!$A$274)<=0.00051,ABS(B29/100-Claves!$A$274)<=0.00051)),"✔ Bien",IF(NOT(ISNUMBER(B29)),"✘ Escribe solo el número (sin texto ni %).",IF(OR(ABS(B29-0.6)<=0.0006,ABS(B29/100-0.6)<=0.0006),"✘ Eso es la condicionada por fila. Aquí te restringes a la COLUMNA.",IF(OR(ABS(B29-0.2)<=0.00051,ABS(B29/100-0.2)<=0.00051),"✘ Divide entre el total de la columna, no entre n.","✘ Revisa el cálculo.")))))
A30: ¿Son independientes? (Sí / No) | C30: =IF(B30="","",IF(OR(UPPER(TRIM(B30))="SÍ",UPPER(TRIM(B30))="SI"),"✔ Bien",IF(UPPER(TRIM(B30))="NO","✘ Compara fᵢⱼ con fᵢ.×f.ⱼ en todas las casillas (o los % de cada fila).",IF(UPPER(TRIM(B30))="NO","✘ Compara fᵢⱼ con fᵢ.×f.ⱼ en todas las casillas (o los % de cada fila).","✘ Revisa la respuesta."))))

Sheet 4_Contingencia_N3
A1: Tabla de doble entrada e independencia · Nivel 3 · Sin ayuda
E2: Aciertos: | F2: =SUMPRODUCT(--(LEFT($C$1:$C$24,1)="✔")) | G2: de 7
A3: Celdas azules: datos. Celdas amarillas: tu respuesta (se ponen verdes si está bien y rojas si no).
A5: 130 trabajadores según edad (filas) y modalidad (columnas).
A6: Edad \ Modalidad | B6: Presencial | C6: Híbrido | D6: Remoto
A7: 18-30 | B7: 10 | C7: 14 | D7: 16
A8: 31-45 | B8: 20 | C8: 18 | D8: 12
A9: 46-65 | B9: 28 | C9: 9 | D9: 3
A11: Preguntas
A12: n (total) | C12: =IF(B12="","",IF(AND(ISNUMBER(B12),ABS(B12-Claves!$A$276)<=0.51),"✔ Bien",IF(NOT(ISNUMBER(B12)),"✘ Escribe solo el número (sin texto ni %).","✘ Revisa el cálculo.")))
A13: Distribución marginal: total de "Híbrido" | C13: =IF(B13="","",IF(AND(ISNUMBER(B13),ABS(B13-Claves!$A$277)<=0.51),"✔ Bien",IF(NOT(ISNUMBER(B13)),"✘ Escribe solo el número (sin texto ni %).","✘ Revisa el cálculo.")))
A14: f₁₁ (proporción de 18-30 y Presencial, en decimal) | C14: =IF(B14="","",IF(AND(ISNUMBER(B14),OR(ABS(B14-Claves!$A$278)<=0.00051,ABS(B14/100-Claves!$A$278)<=0.00051)),"✔ Bien",IF(NOT(ISNUMBER(B14)),"✘ Escribe solo el número (sin texto ni %).","✘ Revisa el cálculo.")))
A15: f₁. × f.₁ (lo que habría si fueran independientes) | C15: =IF(B15="","",IF(AND(ISNUMBER(B15),OR(ABS(B15-Claves!$A$279)<=0.00051,ABS(B15/100-Claves!$A$279)<=0.00051)),"✔ Bien",IF(NOT(ISNUMBER(B15)),"✘ Escribe solo el número (sin texto ni %).","✘ Revisa el cálculo.")))
A16: De los de 46-65, ¿qué proporción es "Remoto"? (Modalidad | Edad = 46-65) | C16: =IF(B16="","",IF(AND(ISNUMBER(B16),OR(ABS(B16-Claves!$A$280)<=0.00051,ABS(B16/100-Claves!$A$280)<=0.00051)),"✔ Bien",IF(NOT(ISNUMBER(B16)),"✘ Escribe solo el número (sin texto ni %).",IF(OR(ABS(B16-0.023076923076923078)<=0.00051,ABS(B16/100-0.023076923076923078)<=0.00051),"✘ En una condicionada se divide entre el total de la FILA, no entre n.",IF(OR(ABS(B16-0.0967741935483871)<=0.00051,ABS(B16/100-0.0967741935483871)<=0.00051),"✘ Eso es Edad | Modalidad: has dividido entre el total de la columna.","✘ Revisa el cálculo.")))))
A17: De los "Presencial", ¿qué proporción es de 31-45? (Edad | Modalidad = Presencial) | C17: =IF(B17="","",IF(AND(ISNUMBER(B17),OR(ABS(B17-Claves!$A$281)<=0.00051,ABS(B17/100-Claves!$A$281)<=0.00051)),"✔ Bien",IF(NOT(ISNUMBER(B17)),"✘ Escribe solo el número (sin texto ni %).",IF(OR(ABS(B17-0.4)<=0.00051,ABS(B17/100-0.4)<=0.00051),"✘ Eso es la condicionada por fila. Aquí te restringes a la COLUMNA.",IF(OR(ABS(B17-0.15384615384615385)<=0.00051,ABS(B17/100-0.15384615384615385)<=0.00051),"✘ Divide entre el total de la columna, no entre n.","✘ Revisa el cálculo.")))))
A18: ¿Son independientes? (Sí / No) | C18: =IF(B18="","",IF(OR(UPPER(TRIM(B18))="NO"),"✔ Bien",IF(UPPER(TRIM(B18))="SI","✘ Compara fᵢⱼ con fᵢ.×f.ⱼ en todas las casillas (o los % de cada fila).",IF(UPPER(TRIM(B18))="SÍ","✘ Compara fᵢⱼ con fᵢ.×f.ⱼ en todas las casillas (o los % de cada fila).","✘ Revisa la respuesta."))))

Sheet 5_Regresion_N1
A1: Regresión con datos · Nivel 1 · Con guía
E2: Aciertos: | F2: =SUMPRODUCT(--(LEFT($C$1:$C$34,1)="✔")) | G2: de 9
A3: Celdas azules: datos. Celdas amarillas: tu respuesta (se ponen verdes si está bien y rojas si no).
A5: Años de experiencia (X) y Salario (cientos de €) (Y) de 8 casos.
A6: Paso 1 · Tabla de trabajo
A7: 💡 Covarianza = Σxy/n − x̄·ȳ. Pendiente b = Sxy / Sx². Comprueba con PENDIENTE(Y;X) y con la línea de tendencia del gráfico.
A8: X | B8: Y | C8: X·Y | D8: X² | E8: Y²
A9: Pista → | C9: ej. =X*Y | D9: ej. =X^2 | E9: ej. =Y^2
A10: 2 | B10: 11.3
A11: 4 | B11: 14.9
A12: 5 | B12: 25.5
A13: 7 | B13: 43.7
A14: 8 | B14: 26.9
A15: 10 | B15: 21.8
A16: 12 | B16: 29.6
A17: 15 | B17: 66.8
A19: Preguntas
A20: Media de X | C20: =IF(B20="","",IF(AND(ISNUMBER(B20),ABS(B20-Claves!$A$307)<=0.007875),"✔ Bien",IF(NOT(ISNUMBER(B20)),"✘ Escribe solo el número (sin texto ni %).","✘ Revisa el cálculo.")))
A21: Media de Y | C21: =IF(B21="","",IF(AND(ISNUMBER(B21),ABS(B21-Claves!$A$308)<=0.030062500000000006),"✔ Bien",IF(NOT(ISNUMBER(B21)),"✘ Escribe solo el número (sin texto ni %).","✘ Revisa el cálculo.")))
A22: Covarianza | C22: =IF(B22="","",IF(AND(ISNUMBER(B22),ABS(B22-Claves!$A$309)<=0.05150781249999997),"✔ Bien",IF(NOT(ISNUMBER(B22)),"✘ Escribe solo el número (sin texto ni %).",IF(ABS(B22-58.866071428571395)<=0.0588660714285714,"✘ Has usado COVARIANZA.M (divide entre n−1). En clase se usa COVARIANZA.P.","✘ Revisa el cálculo."))))
A23: Pendiente b (recta de Y sobre X) | C23: =IF(B23="","",IF(AND(ISNUMBER(B23),ABS(B23-Claves!$A$310)<=0.0031485195797516696),"✔ Bien",IF(NOT(ISNUMBER(B23)),"✘ Escribe solo el número (sin texto ni %).",IF(ABS(B23-0.18587675015379293)<=0.00051,"✘ Esa es la pendiente de X sobre Y. En PENDIENTE va primero la Y: =PENDIENTE(Y;X).",IF(ABS(B23-12.734730313847548)<=0.012734730313847548,"✘ b = Sxy / Sx² (la VARIANZA de X, no la desviación).","✘ Revisa el cálculo.")))))
A24: Término independiente a | C24: =IF(B24="","",IF(AND(ISNUMBER(B24),ABS(B24-Claves!$A$311)<=0.005267908309455606),"✔ Bien",IF(NOT(ISNUMBER(B24)),"✘ Escribe solo el número (sin texto ni %).",IF(ABS(B24-2.2870801985015996)<=0.0051,"✘ Ese es el de la recta de X sobre Y. Usa =INTERSECCION.EJE(Y;X).","✘ Revisa el cálculo."))))
A25: Coeficiente de correlación r | C25: =IF(B25="","",IF(AND(ISNUMBER(B25),ABS(B25-Claves!$A$312)<=0.0007650075733480199),"✔ Bien",IF(NOT(ISNUMBER(B25)),"✘ Escribe solo el número (sin texto ni %).",IF(ABS(B25-0.5852365872798261)<=0.000585236587279826,"✘ Eso es R². r es la raíz (con el signo de b).","✘ Revisa el cálculo."))))
A26: Coeficiente de determinación R² (decimal) | C26: =IF(B26="","",IF(AND(ISNUMBER(B26),OR(ABS(B26-Claves!$A$313)<=0.000585236587279826,ABS(B26/100-Claves!$A$313)<=0.000585236587279826)),"✔ Bien",IF(NOT(ISNUMBER(B26)),"✘ Escribe solo el número (sin texto ni %).",IF(OR(ABS(B26-0.7650075733480199)<=0.0007650075733480199,ABS(B26/100-0.7650075733480199)<=0.0007650075733480199),"✘ Eso es r. R² es r al cuadrado.","✘ Revisa el cálculo."))))
A27: Predicción de Y para X = 3 | C27: =IF(B27="","",IF(AND(ISNUMBER(B27),ABS(B27-Claves!$A$314)<=0.014713467048710616),"✔ Bien",IF(NOT(ISNUMBER(B27)),"✘ Escribe solo el número (sin texto ni %).",IF(ABS(B27-2.8447104489629784)<=0.0051,"✘ Has usado la recta de X sobre Y.","✘ Revisa el cálculo."))))
A28: % de la variabilidad de Y que NO explica la recta | C28: =IF(B28="","",IF(AND(ISNUMBER(B28),OR(ABS(B28-Claves!$A$315)<=0.00051,ABS(B28/100-Claves!$A$315)<=0.00051)),"✔ Bien",IF(NOT(ISNUMBER(B28)),"✘ Escribe solo el número (sin texto ni %).",IF(OR(ABS(B28-0.5852365872798261)<=0.000585236587279826,ABS(B28/100-0.5852365872798261)<=0.000585236587279826),"✘ Ese es el % que SÍ explica (R²). El no explicado es 1 − R².","✘ Revisa el cálculo."))))

Sheet 5_Regresion_N2
A1: Regresión con datos · Nivel 2 · Con cabeceras
E2: Aciertos: | F2: =SUMPRODUCT(--(LEFT($C$1:$C$33,1)="✔")) | G2: de 9
A3: Celdas azules: datos. Celdas amarillas: tu respuesta (se ponen verdes si está bien y rojas si no).
A5: Horas de formación (X) y Errores al mes (Y) de 9 casos.
A6: Paso 1 · Tabla de trabajo
A7: X | B7: Y | C7: X·Y | D7: X² | E7: Y²
A8: 10 | B8: 33
A9: 15 | B9: 34
A10: 20 | B10: 30.8
A11: 25 | B11: 28.5
A12: 30 | B12: 27.5
A13: 35 | B13: 26.2
A14: 40 | B14: 22.6
A15: 50 | B15: 18
A16: 60 | B16: 9.6
A18: Preguntas
A19: Media de X | C19: =IF(B19="","",IF(AND(ISNUMBER(B19),ABS(B19-Claves!$A$343)<=0.03166666666666667),"✔ Bien",IF(NOT(ISNUMBER(B19)),"✘ Escribe solo el número (sin texto ni %).","✘ Revisa el cálculo.")))
A20: Media de Y | C20: =IF(B20="","",IF(AND(ISNUMBER(B20),ABS(B20-Claves!$A$344)<=0.02557777777777778),"✔ Bien",IF(NOT(ISNUMBER(B20)),"✘ Escribe solo el número (sin texto ni %).","✘ Revisa el cálculo.")))
A21: Covarianza | C21: =IF(B21="","",IF(AND(ISNUMBER(B21),ABS(B21-Claves!$A$345)<=0.11101851851851859),"✔ Bien",IF(NOT(ISNUMBER(B21)),"✘ Escribe solo el número (sin texto ni %).",IF(ABS(B21--124.89583333333341)<=0.12489583333333341,"✘ Has usado COVARIANZA.M (divide entre n−1). En clase se usa COVARIANZA.P.","✘ Revisa el cálculo."))))
A22: Pendiente b (recta de Y sobre X) | C22: =IF(B22="","",IF(AND(ISNUMBER(B22),ABS(B22-Claves!$A$346)<=0.00051),"✔ Bien",IF(NOT(ISNUMBER(B22)),"✘ Escribe solo el número (sin texto ni %).",IF(ABS(B22--2.0495913353056223)<=0.002049591335305622,"✘ Esa es la pendiente de X sobre Y. En PENDIENTE va primero la Y: =PENDIENTE(Y;X).",IF(ABS(B22--7.182860837273485)<=0.007182860837273485,"✘ b = Sxy / Sx² (la VARIANZA de X, no la desviación).","✘ Revisa el cálculo.")))))
A23: Término independiente a | C23: =IF(B23="","",IF(AND(ISNUMBER(B23),ABS(B23-Claves!$A$347)<=0.04029418604651164),"✔ Bien",IF(NOT(ISNUMBER(B23)),"✘ Escribe solo el número (sin texto ni %).",IF(ABS(B23-84.0906583763727)<=0.08409065837637271,"✘ Ese es el de la recta de X sobre Y. Usa =INTERSECCION.EJE(Y;X).","✘ Revisa el cálculo."))))
A24: Coeficiente de correlación r | C24: =IF(B24="","",IF(AND(ISNUMBER(B24),ABS(B24-Claves!$A$348)<=0.0009759630527047349),"✔ Bien",IF(NOT(ISNUMBER(B24)),"✘ Escribe solo el número (sin texto ni %).",IF(ABS(B24-0.9759630527047349)<=0.0009759630527047349,"✘ Fíjate en el signo: r tiene el mismo signo que la pendiente.","✘ Revisa el cálculo."))))
A25: Coeficiente de determinación R² (decimal) | C25: =IF(B25="","",IF(AND(ISNUMBER(B25),OR(ABS(B25-Claves!$A$349)<=0.0009525038802447452,ABS(B25/100-Claves!$A$349)<=0.0009525038802447452)),"✔ Bien",IF(NOT(ISNUMBER(B25)),"✘ Escribe solo el número (sin texto ni %).",IF(OR(ABS(B25--0.9759630527047349)<=0.0009759630527047349,ABS(B25/100--0.9759630527047349)<=0.0009759630527047349),"✘ Eso es r. R² es r al cuadrado.","✘ Revisa el cálculo."))))
A26: Predicción de Y para X = 45 | C26: =IF(B26="","",IF(AND(ISNUMBER(B26),ABS(B26-Claves!$A$350)<=0.019381395348837205),"✔ Bien",IF(NOT(ISNUMBER(B26)),"✘ Escribe solo el número (sin texto ni %).",IF(ABS(B26--8.1409517123803)<=0.0081409517123803,"✘ Has usado la recta de X sobre Y.","✘ Revisa el cálculo."))))
A27: % de la variabilidad de Y que NO explica la recta | C27: =IF(B27="","",IF(AND(ISNUMBER(B27),OR(ABS(B27-Claves!$A$351)<=0.00051,ABS(B27/100-Claves!$A$351)<=0.00051)),"✔ Bien",IF(NOT(ISNUMBER(B27)),"✘ Escribe solo el número (sin texto ni %).",IF(OR(ABS(B27-0.9525038802447452)<=0.0009525038802447452,ABS(B27/100-0.9525038802447452)<=0.0009525038802447452),"✘ Ese es el % que SÍ explica (R²). El no explicado es 1 − R².","✘ Revisa el cálculo."))))

Sheet 5_Regresion_N3
A1: Regresión con datos · Nivel 3 · Sin ayuda
E2: Aciertos: | F2: =SUMPRODUCT(--(LEFT($C$1:$C$33,1)="✔")) | G2: de 9
A3: Celdas azules: datos. Celdas amarillas: tu respuesta (se ponen verdes si está bien y rojas si no).
A5: Inversión en publicidad, miles € (X) y Ventas, miles € (Y) de 10 casos.
A6: X | B6: Y
A7: 1 | B7: 59.1
A8: 2 | B8: 62.2
A9: 3 | B9: 80.9
A10: 4 | B10: 78.4
A11: 5 | B11: 85.7
A12: 6 | B12: 104.1
A13: 7 | B13: 117.4
A14: 8 | B14: 125.7
A15: 9 | B15: 134.6
A16: 10 | B16: 137.4
A18: Preguntas
A19: Media de X | C19: =IF(B19="","",IF(AND(ISNUMBER(B19),ABS(B19-Claves!$A$352)<=0.0055),"✔ Bien",IF(NOT(ISNUMBER(B19)),"✘ Escribe solo el número (sin texto ni %).","✘ Revisa el cálculo.")))
A20: Media de Y | C20: =IF(B20="","",IF(AND(ISNUMBER(B20),ABS(B20-Claves!$A$353)<=0.09855),"✔ Bien",IF(NOT(ISNUMBER(B20)),"✘ Escribe solo el número (sin texto ni %).","✘ Revisa el cálculo.")))
A21: Covarianza | C21: =IF(B21="","",IF(AND(ISNUMBER(B21),ABS(B21-Claves!$A$354)<=0.07854499999999996),"✔ Bien",IF(NOT(ISNUMBER(B21)),"✘ Escribe solo el número (sin texto ni %).",IF(ABS(B21-87.27222222222218)<=0.08727222222222218,"✘ Has usado COVARIANZA.M (divide entre n−1). En clase se usa COVARIANZA.P.","✘ Revisa el cálculo."))))
A22: Pendiente b (recta de Y sobre X) | C22: =IF(B22="","",IF(AND(ISNUMBER(B22),ABS(B22-Claves!$A$355)<=0.009520606060606056),"✔ Bien",IF(NOT(ISNUMBER(B22)),"✘ Escribe solo el número (sin texto ni %).",IF(ABS(B22-0.10210641192387611)<=0.00051,"✘ Esa es la pendiente de X sobre Y. En PENDIENTE va primero la Y: =PENDIENTE(Y;X).",IF(ABS(B22-27.34585897408056)<=0.02734585897408056,"✘ b = Sxy / Sx² (la VARIANZA de X, no la desviación).","✘ Revisa el cálculo.")))))
A23: Término independiente a | C23: =IF(B23="","",IF(AND(ISNUMBER(B23),ABS(B23-Claves!$A$356)<=0.04618666666666669),"✔ Bien",IF(NOT(ISNUMBER(B23)),"✘ Escribe solo el número (sin texto ni %).",IF(ABS(B23--4.56258689509799)<=0.0051,"✘ Ese es el de la recta de X sobre Y. Usa =INTERSECCION.EJE(Y;X).","✘ Revisa el cálculo."))))
A24: Coeficiente de correlación r | C24: =IF(B24="","",IF(AND(ISNUMBER(B24),ABS(B24-Claves!$A$357)<=0.0009859588856484804),"✔ Bien",IF(NOT(ISNUMBER(B24)),"✘ Escribe solo el número (sin texto ni %).",IF(ABS(B24-0.9721149241891933)<=0.0009721149241891933,"✘ Eso es R². r es la raíz (con el signo de b).","✘ Revisa el cálculo."))))
A25: Coeficiente de determinación R² (decimal) | C25: =IF(B25="","",IF(AND(ISNUMBER(B25),OR(ABS(B25-Claves!$A$358)<=0.0009721149241891933,ABS(B25/100-Claves!$A$358)<=0.0009721149241891933)),"✔ Bien",IF(NOT(ISNUMBER(B25)),"✘ Escribe solo el número (sin texto ni %).",IF(OR(ABS(B25-0.9859588856484804)<=0.0009859588856484804,ABS(B25/100-0.9859588856484804)<=0.0009859588856484804),"✘ Eso es r. R² es r al cuadrado.","✘ Revisa el cálculo."))))
A26: Predicción de Y para X = 11 | C26: =IF(B26="","",IF(AND(ISNUMBER(B26),ABS(B26-Claves!$A$359)<=0.1509133333333333),"✔ Bien",IF(NOT(ISNUMBER(B26)),"✘ Escribe solo el número (sin texto ni %).",IF(ABS(B26--3.4394163639353525)<=0.0051,"✘ Has usado la recta de X sobre Y.","✘ Revisa el cálculo."))))
A27: % de la variabilidad de Y que NO explica la recta | C27: =IF(B27="","",IF(AND(ISNUMBER(B27),OR(ABS(B27-Claves!$A$360)<=0.00051,ABS(B27/100-Claves!$A$360)<=0.00051)),"✔ Bien",IF(NOT(ISNUMBER(B27)),"✘ Escribe solo el número (sin texto ni %).",IF(OR(ABS(B27-0.9721149241891933)<=0.0009721149241891933,ABS(B27/100-0.9721149241891933)<=0.0009721149241891933),"✘ Ese es el % que SÍ explica (R²). El no explicado es 1 − R².","✘ Revisa el cálculo."))))

Sheet 6_Reg_resumen_N1
A1: Regresión a partir de resúmenes · Nivel 1 · Con guía
E2: Aciertos: | F2: =SUMPRODUCT(--(LEFT($C$1:$C$25,1)="✔")) | G2: de 5
A3: Celdas azules: datos. Celdas amarillas: tu respuesta (se ponen verdes si está bien y rojas si no).
A5: X = gasto en formación (miles €), Y = productividad (unidades). Datos resumidos:
A6: Dato | B6: Valor
A7: x̄ | B7: 40
A8: ȳ | B8: 620
A9: Sx² (varianza de X) | B9: 144
A10: Sy² (varianza de Y) | B10: 22500
A11: Sxy (covarianza) | B11: 1440
A13: 💡 b = Sxy / Sx² · a = ȳ − b·x̄ · r = Sxy / (Sx·Sy) · R² = r²
A14: Preguntas
A15: Pendiente b | C15: =IF(B15="","",IF(AND(ISNUMBER(B15),ABS(B15-Claves!$A$361)<=0.01),"✔ Bien",IF(NOT(ISNUMBER(B15)),"✘ Escribe solo el número (sin texto ni %).",IF(ABS(B15-120)<=0.12,"✘ b = Sxy / Sx² : divide entre la VARIANZA de X (Sx al cuadrado).",IF(ABS(B15-0.064)<=0.00051,"✘ Esa es la pendiente de X sobre Y (divides entre Sy²).","✘ Revisa el cálculo.")))))
A16: Término independiente a | C16: =IF(B16="","",IF(AND(ISNUMBER(B16),ABS(B16-Claves!$A$362)<=0.22),"✔ Bien",IF(NOT(ISNUMBER(B16)),"✘ Escribe solo el número (sin texto ni %).","✘ Revisa el cálculo.")))
A17: Correlación r | C17: =IF(B17="","",IF(AND(ISNUMBER(B17),ABS(B17-Claves!$A$363)<=0.0008),"✔ Bien",IF(NOT(ISNUMBER(B17)),"✘ Escribe solo el número (sin texto ni %).","✘ Revisa el cálculo.")))
A18: R² (decimal) | C18: =IF(B18="","",IF(AND(ISNUMBER(B18),OR(ABS(B18-Claves!$A$364)<=0.0006400000000000002,ABS(B18/100-Claves!$A$364)<=0.0006400000000000002)),"✔ Bien",IF(NOT(ISNUMBER(B18)),"✘ Escribe solo el número (sin texto ni %).","✘ Revisa el cálculo.")))
A19: Predicción de Y para 55000 € | C19: =IF(B19="","",IF(AND(ISNUMBER(B19),ABS(B19-Claves!$A$365)<=0.77),"✔ Bien",IF(NOT(ISNUMBER(B19)),"✘ Escribe solo el número (sin texto ni %).",IF(ABS(B19-550220)<=550.22,"✘ Cuidado con las unidades: si X está en miles, 55000 € es X = 55.","✘ Revisa el cálculo."))))

Sheet 6_Reg_resumen_N2
A1: Regresión a partir de resúmenes · Nivel 2 · Con cabeceras
E2: Aciertos: | F2: =SUMPRODUCT(--(LEFT($C$1:$C$25,1)="✔")) | G2: de 5
A3: Celdas azules: datos. Celdas amarillas: tu respuesta (se ponen verdes si está bien y rojas si no).
A5: X = años de antigüedad, Y = días de baja al año ×10. Datos resumidos:
A6: Dato | B6: Valor
A7: x̄ | B7: 8
A8: ȳ | B8: 1800
A9: Sx (desviación típica de X) | B9: 3
A10: Sy (desviación típica de Y) | B10: 300
A11: Sxy (covarianza) | B11: -540
A13: 💡 Cuidado: aquí te dan desviaciones típicas (S), no varianzas (S²).
A14: Preguntas
A15: Pendiente b | C15: =IF(B15="","",IF(AND(ISNUMBER(B15),ABS(B15-Claves!$A$366)<=0.06),"✔ Bien",IF(NOT(ISNUMBER(B15)),"✘ Escribe solo el número (sin texto ni %).",IF(ABS(B15--180)<=0.18,"✘ b = Sxy / Sx² : divide entre la VARIANZA de X (Sx al cuadrado).",IF(ABS(B15--0.006)<=0.00051,"✘ Esa es la pendiente de X sobre Y (divides entre Sy²).","✘ Revisa el cálculo.")))))
